Workbook

Sheet Petunjuk
A1: PERHITUNGAN MANUAL SISTEM - Peramalan, Kebutuhan Bahan, Safety Stock, ROP, Rekomendasi Beli
A2: Restoran X | contoh 2 menu (Nasi Goreng Spesial, Mie Goreng Spesial) | data dummy versi 2: Jun 2021 - Mei 2026 (60 bulan)
A4: ALUR SHEET
A5: Data (input) > TES_*_Uji dan Census_*_Uji: model dilatih 48 bulan, diuji 12 bulan > Pilih_Metode: MAPE holdout terendah (seri = TES) > TES_* dan Census_* (final): dilatih ulang 60 bulan, ramal 12 bulan ke depan
A6: > Prediksi_Periode: hasil untuk tgl_awal-tgl_akhir > Kebutuhan_Bahan: KB = jumlah(BOM x prediksi) > Riwayat_Bahan: pemakaian historis & Dmax > Restock: SS, ROP, status, jumlah beli. Bobot_Filter: bobot MA/Henderson/musiman.
A8: KEPUTUSAN MODEL
A9: Model MULTIPLIKATIF untuk TES dan Census II, dengan alasan teoretis: efek musiman berupa persentase dari level (Ramadan, Desember, Januari, dst.), sehingga amplitudonya ikut naik bila level naik, dan efeknya sebanding antar menu yang volumenya berbeda.
A10: Uji empiris pada 53 menu (holdout 12 bulan) hampir seri: TES multiplikatif menang di 21 menu (median MAPE 6.75% vs aditif 6.70%); Census II multiplikatif menang di 4 menu (median 8.34% vs aditif 8.11%). Jadi pilihan ini bertumpu pada sifat data, bukan hasil uji.
A11: Kelemahan multiplikatif: tidak bisa untuk nilai <= 0 (tidak terjadi pada penjualan). Kelebihan aditif: lebih sederhana bila amplitudo musiman konstan.
A12: Filter musiman: iterasi 1 memakai 3x3, iterasi 2 memakai 3x5 (urutan standar X-11). Tren memakai Henderson 13 suku.
A14: ASUMSI & KETERBATASAN (baca sebelum dipakai)
A15: 1. MAPE dihitung pada holdout (latih t=1..48, uji t=49..60), lalu model final dilatih ulang dengan seluruh 60 bulan. alpha/beta/gamma hasil optimasi SSE di Python (dibulatkan); sistem nanti mengoptimasi sendiri.
... A23: Font biru = input/konstanta | Hitam = rumus | Hijau = tautan dari sheet lain | Sel kuning = asumsi/isian yang perlu Anda ganti.

Sheet Data
A1: DATA PENJUALAN BULANAN (porsi) - input
A2: Sumber: data_penjualan_restoran_x_v2.xlsx (data dummy versi 2, Jun 2021 - Mei 2026), menu No.1 dan No.4. Nilai disalin apa adanya.
A4: t | B4: Periode | C4: Hari dlm bulan | D4: Nasi Goreng Spesial | E4: Mie Goreng Spesial
A5: 1 | B5: 44348 | C5: =DAY(EOMONTH(B5,0)) -> 30 | D5: 230 | E5: 221
A6: 2 | B6: 44378 | C6: =DAY(EOMONTH(B6,0)) -> 31 | D6: 268 | E6: 238
A7: 3 | B7: 44409 | C7: =DAY(EOMONTH(B7,0)) -> 31 | D7: 220 | E7: 222
A8: 4 | B8: 44440 | C8: =DAY(EOMONTH(B8,0)) -> 30 | D8: 260 | E8: 204
A9: 5 | B9: 44470 | C9: =DAY(EOMONTH(B9,0)) -> 31 | D9: 252 | E9: 221
A10: 6 | B10: 44501 | C10: =DAY(EOMONTH(B10,0)) -> 30 | D10: 241 | E10: 225
A11: 7 | B11: 44531 | C11: =DAY(EOMONTH(B11,0)) -> 31 | D11: 302 | E11: 278
A12: 8 | B12: 44562 | C12: =DAY(EOMONTH(B12,0)) -> 31 | D12: 288 | E12: 245
A13: 9 | B13: 44593 | C13: =DAY(EOMONTH(B13,0)) -> 28 | D13: 244 | E13: 179
A14: 10 | B14: 44621 | C14: =DAY(EOMONTH(B14,0)) -> 31 | D14: 246 | E14: 223
A15: 11 | B15: 44652 | C15: =DAY(EOMONTH(B15,0)) -> 30 | D15: 346 | E15: 293
A16: 12 | B16: 44682 | C16: =DAY(EOMONTH(B16,0)) -> 31 | D16: 289 | E16: 241
... A64: 60 | B64: 46143 | C64: =DAY(EOMONTH(B64,0)) -> 31 | D64: 295 | E64: 294

Sheet Bobot_Filter
A1: BOBOT FILTER (definisi tetap)
A3: MA 2x12 (13 suku)
A4: k=-6 | B4: =1/24 -> 0.041666667
A5: k=-5 | B5: =1/12 -> 0.083333333
A6: k=-4 | B6: =1/12 -> 0.083333333
A7: k=-3 | B7: =1/12 -> 0.083333333
A8: k=-2 | B8: =1/12 -> 0.083333333
A9: k=-1 | B9: =1/12 -> 0.083333333
A10: k=0 | B10: =1/12 -> 0.083333333
A11: k=1 | B11: =1/12 -> 0.083333333
A12: k=2 | B12: =1/12 -> 0.083333333
A13: k=3 | B13: =1/12 -> 0.083333333
A14: k=4 | B14: =1/12 -> 0.083333333
A15: k=5 | B15: =1/12 -> 0.083333333
A16: k=6 | B16: =1/24 -> 0.041666667
A17: Jumlah | B17: =SUM(B4:B16) -> 1
A19: Henderson 13 suku: r = m+2, m = 6 | B19: 8 | C19: w(j) = 315[(r-1)^2-j^2][r^2-j^2][(r+1)^2-j^2][3r^2-16-11j^2] / (8r(r^2-1)(4r^2-1)(4r^2-9)(4r^2-25))
A20: -6 | B20: =315*(($B$19-1)^2-A20^2)*($B$19^2-A20^2)*(($B$19+1)^2-A20^2)*(3*$B$19^2-16-11*A20^2)/(8*$B$19*($B$19^2-1)*(4*$B$19^2-1)*(4*$B$19^2-9)*(4*$B$19^2-25)) -> -0.019349845
A21: -5 | B21: =315*(($B$19-1)^2-A21^2)*($B$19^2-A21^2)*(($B$19+1)^2-A21^2)*(3*$B$19^2-16-11*A21^2)/(8*$B$19*($B$19^2-1)*(4*$B$19^2-1)*(4*$B$19^2-9)*(4*$B$19^2-25)) -> -0.027863777
A22: -4 | B22: =315*(($B$19-1)^2-A22^2)*($B$19^2-A22^2)*(($B$19+1)^2-A22^2)*(3*$B$19^2-16-11*A22^2)/(8*$B$19*($B$19^2-1)*(4*$B$19^2-1)*(4*$B$19^2-9)*(4*$B$19^2-25)) -> 0
A23: -3 | B23: =315*(($B$19-1)^2-A23^2)*($B$19^2-A23^2)*(($B$19+1)^2-A23^2)*(3*$B$19^2-16-11*A23^2)/(8*$B$19*($B$19^2-1)*(4*$B$19^2-1)*(4*$B$19^2-9)*(4*$B$19^2-25)) -> 0.065491784
A24: -2 | B24: =315*(($B$19-1)^2-A24^2)*($B$19^2-A24^2)*(($B$19+1)^2-A24^2)*(3*$B$19^2-16-11*A24^2)/(8*$B$19*($B$19^2-1)*(4*$B$19^2-1)*(4*$B$19^2-9)*(4*$B$19^2-25)) -> 0.14735651
A25: -1 | B25: =315*(($B$19-1)^2-A25^2)*($B$19^2-A25^2)*(($B$19+1)^2-A25^2)*(3*$B$19^2-16-11*A25^2)/(8*$B$19*($B$19^2-1)*(4*$B$19^2-1)*(4*$B$19^2-9)*(4*$B$19^2-25)) -> 0.21433675
A26: 0 | B26: =315*(($B$19-1)^2-A26^2)*($B$19^2-A26^2)*(($B$19+1)^2-A26^2)*(3*$B$19^2-16-11*A26^2)/(8*$B$19*($B$19^2-1)*(4*$B$19^2-1)*(4*$B$19^2-9)*(4*$B$19^2-25)) -> 0.24005716
A27: 1 | B27: =315*(($B$19-1)^2-A27^2)*($B$19^2-A27^2)*(($B$19+1)^2-A27^2)*(3*$B$19^2-16-11*A27^2)/(8*$B$19*($B$19^2-1)*(4*$B$19^2-1)*(4*$B$19^2-9)*(4*$B$19^2-25)) -> 0.21433675
A28: 2 | B28: =315*(($B$19-1)^2-A28^2)*($B$19^2-A28^2)*(($B$19+1)^2-A28^2)*(3*$B$19^2-16-11*A28^2)/(8*$B$19*($B$19^2-1)*(4*$B$19^2-1)*(4*$B$19^2-9)*(4*$B$19^2-25)) -> 0.14735651
A29: 3 | B29: =315*(($B$19-1)^2-A29^2)*($B$19^2-A29^2)*(($B$19+1)^2-A29^2)*(3*$B$19^2-16-11*A29^2)/(8*$B$19*($B$19^2-1)*(4*$B$19^2-1)*(4*$B$19^2-9)*(4*$B$19^2-25)) -> 0.065491784
A30: 4 | B30: =315*(($B$19-1)^2-A30^2)*($B$19^2-A30^2)*(($B$19+1)^2-A30^2)*(3*$B$19^2-16-11*A30^2)/(8*$B$19*($B$19^2-1)*(4*$B$19^2-1)*(4*$B$19^2-9)*(4*$B$19^2-25)) -> 0
A31: 5 | B31: =315*(($B$19-1)^2-A31^2)*($B$19^2-A31^2)*(($B$19+1)^2-A31^2)*(3*$B$19^2-16-11*A31^2)/(8*$B$19*($B$19^2-1)*(4*$B$19^2-1)*(4*$B$19^2-9)*(4*$B$19^2-25)) -> -0.027863777
A32: 6 | B32: =315*(($B$19-1)^2-A32^2)*($B$19^2-A32^2)*(($B$19+1)^2-A32^2)*(3*$B$19^2-16-11*A32^2)/(8*$B$19*($B$19^2-1)*(4*$B$19^2-1)*(4*$B$19^2-9)*(4*$B$19^2-25)) -> -0.019349845
A33: Jumlah | B33: =SUM(B20:B32) -> 1
A36: Filter musiman 3x3 (5 suku, selang 12 bulan)
A37: Offset (bulan) | B37: -24 | C37: -12 | D37: 0 | E37: 12 | F37: 24
A38: Bobot | B38: =1/9 -> 0.11111111 | C38: =2/9 -> 0.22222222 | D38: =3/9 -> 0.33333333 | E38: =2/9 -> 0.22222222 | F38: =1/9 -> 0.11111111 | H38: =SUM(B38:F38) -> 1
A41: Filter musiman 3x5 (7 suku, selang 12 bulan)
A42: Offset (bulan) | B42: -36 | C42: -24 | D42: -12 | E42: 0 | F42: 12 | G42: 24 | H42: 36
A43: Bobot | B43: =1/15 -> 0.066666667 | C43: =2/15 -> 0.13333333 | D43: =3/15 -> 0.2 | E43: =3/15 -> 0.2 | F43: =3/15 -> 0.2 | G43: =2/15 -> 0.13333333 | H43: =1/15 -> 0.066666667 | I43: =SUM(B43:H43) -> 1

Sheet TES_NasiGoreng_Uji
A1: TRIPLE EXPONENTIAL SMOOTHING (Holt-Winters multiplikatif) - Nasi Goreng Spesial - UJI (latih t=1..48, uji t=49..60)
A3: alpha (level) | B3: 0.01 | C3: alpha/beta/gamma = hasil optimasi SSE (Python, L-BFGS-B, batas 0,01-0,99) pada data latih t=1..48, dibulatkan 2 desimal. Bisa diganti manual; di Excel bisa dioptimasi dengan Solver pada B9.
A4: beta (tren) | B4: 0.37 | C4: Inisialisasi: L12 = rata-rata musim 1; b12 = (rata-rata musim 2 - rata-rata musim 1)/m; S_t = Y_t/L12 (t=1..12).
A5: gamma (musiman) | B5: 0.94 | C5: F_t=(L_(t-1)+b_(t-1))*S_(t-m); L_t=a*Y_t/S_(t-m)+(1-a)(L_(t-1)+b_(t-1)); b_t=b(L_t-L_(t-1))+(1-b)b_(t-1); S_t=g*Y_t/L_t+(1-g)S_(t-m).
A6: m (panjang musim) | B6: 12 | C6: Ramalan: F_(n+h) = (L_n + h*b_n)*S_(n+h-m), n=48. Baris ramalan dibandingkan dengan aktual (holdout).
A7: MAPE holdout (t=49..60) | B7: =AVERAGE(H60:H71) -> 0.069927551
A8: MAPE in-sample (t=13..48) | B8: =AVERAGE(H24:H59) -> 0.063320134
A9: SSE in-sample (t=13..48) | B9: =SUMXMY2(C24:C59,G24:G59) -> 19134.013
A11: t | B11: Periode | C11: Aktual (Y) | D11: Level (L) | E11: Tren (b) | F11: Musiman (S) | G11: Fitted / Ramalan | H11: APE | I11: Tahap
A12: 1 | B12: =Data!B5 -> 44348 | C12: =Data!D5 -> 230 | F12: =C12/$D$23 -> 0.86629002 | I12: Inisialisasi
A13: 2 | B13: =Data!B6 -> 44378 | C13: =Data!D6 -> 268 | F13: =C13/$D$23 -> 1.0094162 | I13: Inisialisasi
A14: 3 | B14: =Data!B7 -> 44409 | C14: =Data!D7 -> 220 | F14: =C14/$D$23 -> 0.82862524 | I14: Inisialisasi
A15: 4 | B15: =Data!B8 -> 44440 | C15: =Data!D8 -> 260 | F15: =C15/$D$23 -> 0.97928437 | I15: Inisialisasi
A16: 5 | B16: =Data!B9 -> 44470 | C16: =Data!D9 -> 252 | F16: =C16/$D$23 -> 0.94915254 | I16: Inisialisasi
A17: 6 | B17: =Data!B10 -> 44501 | C17: =Data!D10 -> 241 | F17: =C17/$D$23 -> 0.90772128 | I17: Inisialisasi
A18: 7 | B18: =Data!B11 -> 44531 | C18: =Data!D11 -> 302 | F18: =C18/$D$23 -> 1.1374765 | I18: Inisialisasi
A19: 8 | B19: =Data!B12 -> 44562 | C19: =Data!D12 -> 288 | F19: =C19/$D$23 -> 1.0847458 | I19: Inisialisasi
A20: 9 | B20: =Data!B13 -> 44593 | C20: =Data!D13 -> 244 | F20: =C20/$D$23 -> 0.91902072 | I20: Inisialisasi
A21: 10 | B21: =Data!B14 -> 44621 | C21: =Data!D14 -> 246 | F21: =C21/$D$23 -> 0.92655367 | I21: Inisialisasi
A22: 11 | B22: =Data!B15 -> 44652 | C22: =Data!D15 -> 346 | F22: =C22/$D$23 -> 1.3032015 | I22: Inisialisasi
A23: 12 | B23: =Data!B16 -> 44682 | C23: =Data!D16 -> 289 | D23: =AVERAGE(C12:C23) -> 265.5 | E23: =(AVERAGE(C24:C35)-AVERAGE(C12:C23))/$B$6 -> 0.84027778 | F23: =C23/$D$23 -> 1.0885122 | I23: Inisialisasi
A24: 13 | B24: =Data!B17 -> 44713 | C24: =Data!D17 -> 251 | D24: =$B$3*(C24/F12)+(1-$B$3)*(D23+E23) -> 266.57429 | E24: =$B$4*(D24-D23)+(1-$B$4)*E23 -> 0.92686158 | F24: =$B$5*(C24/D24)+(1-$B$5)*F12 -> 0.93705901 | G24: =(D23+E23)*F12 -> 230.72792 | H24: =ABS(C24-G24)/C24 -> 0.080765242 | I24: Smoothing
A25: 14 | B25: =Data!B18 -> 44743 | C25: =Data!D18 -> 277 | D25: =$B$3*(C25/F13)+(1-$B$3)*(D24+E24) -> 267.5703 | E25: =$B$4*(D25-D24)+(1-$B$4)*E24 -> 0.95244669 | F25: =$B$5*(C25/D25)+(1-$B$5)*F13 -> 1.0336924 | G25: =(D24+E24)*F13 -> 270.01999 | H25: =ABS(C25-G25)/C25 -> 0.025198582 | I25: Smoothing
A26: 15 | B26: =Data!B19 -> 44774 | C26: =Data!D19 -> 256 | D26: =$B$3*(C26/F14)+(1-$B$3)*(D25+E25) -> 268.92697 | E26: =$B$4*(D26-D25)+(1-$B$4)*E25 -> 1.1020107 | F26: =$B$5*(C26/D26)+(1-$B$5)*F14 -> 0.94453293 | G26: =(D25+E25)*F14 -> 222.50472 | H26: =ABS(C26-G26)/C26 -> 0.13084093 | I26: Smoothing
A27: 16 | B27: =Data!B20 -> 44805 | C27: =Data!D20 -> 247 | D27: =$B$3*(C27/F15)+(1-$B$3)*(D26+E26) -> 269.85094 | E27: =$B$4*(D27-D26)+(1-$B$4)*E26 -> 1.036136 | F27: =$B$5*(C27/D27)+(1-$B$5)*F15 -> 0.91915798 | G27: =(D26+E26)*F15 -> 264.43516 | H27: =ABS(C27-G27)/C27 -> 0.070587702 | I27: Smoothing
A28: 17 | B28: =Data!B21 -> 44835 | C28: =Data!D21 -> 250 | D28: =$B$3*(C28/F16)+(1-$B$3)*(D27+E27) -> 270.81214 | E28: =$B$4*(D28-D27)+(1-$B$4)*E27 -> 1.0084074 | F28: =$B$5*(C28/D28)+(1-$B$5)*F16 -> 0.92470937 | G28: =(D27+E27)*F16 -> 257.11316 | H28: =ABS(C28-G28)/C28 -> 0.02845264 | I28: Smoothing
A29: 18 | B29: =Data!B22 -> 44866 | C29: =Data!D22 -> 264 | D29: =$B$3*(C29/F17)+(1-$B$3)*(D28+E28) -> 272.01072 | E29: =$B$4*(D29-D28)+(1-$B$4)*E28 -> 1.0787726 | F29: =$B$5*(C29/D29)+(1-$B$5)*F17 -> 0.96678026 | G29: =(D28+E28)*F17 -> 246.73729 | H29: =ABS(C29-G29)/C29 -> 0.065389043 | I29: Smoothing
A30: 19 | B30: =Data!B23 -> 44896 | C30: =Data!D23 -> 320 | D30: =$B$3*(C30/F18)+(1-$B$3)*(D29+E29) -> 273.17184 | E30: =$B$4*(D30-D29)+(1-$B$4)*E29 -> 1.1092421 | F30: =$B$5*(C30/D30)+(1-$B$5)*F18 -> 1.169387 | G30: =(D29+E29)*F18 -> 310.63287 | H30: =ABS(C30-G30)/C30 -> 0.029272282 | I30: Smoothing
A31: 20 | B31: =Data!B24 -> 44927 | C31: =Data!D24 -> 278 | D31: =$B$3*(C31/F19)+(1-$B$3)*(D30+E30) -> 274.10109 | E31: =$B$4*(D31-D30)+(1-$B$4)*E30 -> 1.0426427 | F31: =$B$5*(C31/D31)+(1-$B$5)*F19 -> 1.0184556 | G31: =(D30+E30)*F19 -> 297.52525 | H31: =ABS(C31-G31)/C31 -> 0.070234695 | I31: Smoothing
A32: 21 | B32: =Data!B25 -> 44958 | C32: =Data!D25 -> 254 | D32: =$B$3*(C32/F20)+(1-$B$3)*(D31+E31) -> 275.1561 | E32: =$B$4*(D32-D31)+(1-$B$4)*E31 -> 1.0472212 | F32: =$B$5*(C32/D32)+(1-$B$5)*F20 -> 0.92286686 | G32: =(D31+E31)*F20 -> 252.86279 | H32: =ABS(C32-G32)/C32 -> 0.0044772146 | I32: Smoothing
A33: 22 | B33: =Data!B26 -> 44986 | C33: =Data!D26 -> 297 | D33: =$B$3*(C33/F21)+(1-$B$3)*(D32+E32) -> 276.64672 | E33: =$B$4*(D33-D32)+(1-$B$4)*E32 -> 1.2112768 | F33: =$B$5*(C33/D33)+(1-$B$5)*F21 -> 1.0647503 | G33: =(D32+E32)*F21 -> 255.91721 | H33: =ABS(C33-G33)/C33 -> 0.13832591 | I33: Smoothing
A34: 23 | B34: =Data!B27 -> 45017 | C34: =Data!D27 -> 352 | D34: =$B$3*(C34/F22)+(1-$B$3)*(D33+E33) -> 277.78046 | E34: =$B$4*(D34-D33)+(1-$B$4)*E33 -> 1.1825872 | F34: =$B$5*(C34/D34)+(1-$B$5)*F22 -> 1.2693486 | G34: =(D33+E33)*F22 -> 362.10496 | H34: =ABS(C34-G34)/C34 -> 0.028707268 | I34: Smoothing
A35: 24 | B35: =Data!B28 -> 45047 | C35: =Data!D28 -> 261 | D35: =$B$3*(C35/F23)+(1-$B$3)*(D34+E34) -> 278.57118 | E35: =$B$4*(D35-D34)+(1-$B$4)*E34 -> 1.0375981 | F35: =$B$5*(C35/D35)+(1-$B$5)*F23 -> 0.94601921 | G35: =(D34+E34)*F23 -> 303.65469 | H35: =ABS(C35-G35)/C35 -> 0.16342792 | I35: Smoothing
... A59: 48 | B59: =Data!B52 -> 45778 | C59: =Data!D52 -> 278 | D59: =$B$3*(C59/F47)+(1-$B$3)*(D58+E58) -> 309.51856 | E59: =$B$4*(D59-D58)+(1-$B$4)*E58 -> 1.3053539 | F59: =$B$5*(C59/D59)+(1-$B$5)*F47 -> 0.90231847 | G59: =(D58+E58)*F47 -> 299.62151 | H59: =ABS(C59-G59)/C59 -> 0.077775209 | I59: Smoothing
A60: 49 | B60: =EDATE(B59,1) -> 45809 | C60: =Data!D53 -> 330 | G60: =($D$59+(A60-48)*$E$59)*F48 -> 285.12161 | H60: =ABS(C60-G60)/C60 -> 0.13599511 | I60: Ramalan (holdout)
A61: 50 | B61: =EDATE(B60,1) -> 45839 | C61: =Data!D54 -> 375 | G61: =($D$59+(A61-48)*$E$59)*F49 -> 317.08237 | H61: =ABS(C61-G61)/C61 -> 0.154447 | I61: Ramalan (holdout)
A62: 51 | B62: =EDATE(B61,1) -> 45870 | C62: =Data!D55 -> 317 | G62: =($D$59+(A62-48)*$E$59)*F50 -> 300.12467 | H62: =ABS(C62-G62)/C62 -> 0.053234489 | I62: Ramalan (holdout)
A63: 52 | B63: =EDATE(B62,1) -> 45901 | C63: =Data!D56 -> 306 | G63: =($D$59+(A63-48)*$E$59)*F51 -> 308.8716 | H63: =ABS(C63-G63)/C63 -> 0.0093843215 | I63: Ramalan (holdout)
A64: 53 | B64: =EDATE(B63,1) -> 45931 | C64: =Data!D57 -> 285 | G64: =($D$59+(A64-48)*$E$59)*F52 -> 297.66777 | H64: =ABS(C64-G64)/C64 -> 0.044448302 | I64: Ramalan (holdout)
A65: 54 | B65: =EDATE(B64,1) -> 45962 | C65: =Data!D58 -> 311 | G65: =($D$59+(A65-48)*$E$59)*F53 -> 289.14774 | H65: =ABS(C65-G65)/C65 -> 0.070264492 | I65: Ramalan (holdout)
...

Sheet TES_NasiGoreng
A1: TRIPLE EXPONENTIAL SMOOTHING (Holt-Winters multiplikatif) - Nasi Goreng Spesial - FINAL (latih semua 60 bulan, ramal 12 bulan ke depan)
A3: alpha (level) | B3: 0.01 | C3: alpha/beta/gamma = hasil optimasi SSE (Python, L-BFGS-B, batas 0,01-0,99) pada data latih t=1..60, dibulatkan 2 desimal. Bisa diganti manual; di Excel bisa dioptimasi dengan Solver pada B9.
A4: beta (tren) | B4: 0.29 | C4: Inisialisasi: L12 = rata-rata musim 1; b12 = (rata-rata musim 2 - rata-rata musim 1)/m; S_t = Y_t/L12 (t=1..12).
A5: gamma (musiman) | B5: 0.8 | C5: F_t=(L_(t-1)+b_(t-1))*S_(t-m); L_t=a*Y_t/S_(t-m)+(1-a)(L_(t-1)+b_(t-1)); b_t=b(L_t-L_(t-1))+(1-b)b_(t-1); S_t=g*Y_t/L_t+(1-g)S_(t-m).
A6: m (panjang musim) | B6: 12 | C6: Ramalan: F_(n+h) = (L_n + h*b_n)*S_(n+h-m), n=60.
A7: MAPE holdout | B7: n/a (lihat sheet _Uji)
A8: MAPE in-sample (t=13..60) | B8: =AVERAGE(H24:H71) -> 0.063164963
A9: SSE in-sample (t=13..60) | B9: =SUMXMY2(C24:C71,G24:G71) -> 29491.337
A11: t | B11: Periode | C11: Aktual (Y) | D11: Level (L) | E11: Tren (b) | F11: Musiman (S) | G11: Fitted / Ramalan | H11: APE | I11: Tahap
A12: 1 | B12: =Data!B5 -> 44348 | C12: =Data!D5 -> 230 | F12: =C12/$D$23 -> 0.86629002 | I12: Inisialisasi
A13: 2 | B13: =Data!B6 -> 44378 | C13: =Data!D6 -> 268 | F13: =C13/$D$23 -> 1.0094162 | I13: Inisialisasi
A14: 3 | B14: =Data!B7 -> 44409 | C14: =Data!D7 -> 220 | F14: =C14/$D$23 -> 0.82862524 | I14: Inisialisasi
A15: 4 | B15: =Data!B8 -> 44440 | C15: =Data!D8 -> 260 | F15: =C15/$D$23 -> 0.97928437 | I15: Inisialisasi
A16: 5 | B16: =Data!B9 -> 44470 | C16: =Data!D9 -> 252 | F16: =C16/$D$23 -> 0.94915254 | I16: Inisialisasi
A17: 6 | B17: =Data!B10 -> 44501 | C17: =Data!D10 -> 241 | F17: =C17/$D$23 -> 0.90772128 | I17: Inisialisasi
A18: 7 | B18: =Data!B11 -> 44531 | C18: =Data!D11 -> 302 | F18: =C18/$D$23 -> 1.1374765 | I18: Inisialisasi
A19: 8 | B19: =Data!B12 -> 44562 | C19: =Data!D12 -> 288 | F19: =C19/$D$23 -> 1.0847458 | I19: Inisialisasi
A20: 9 | B20: =Data!B13 -> 44593 | C20: =Data!D13 -> 244 | F20: =C20/$D$23 -> 0.91902072 | I20: Inisialisasi
A21: 10 | B21: =Data!B14 -> 44621 | C21: =Data!D14 -> 246 | F21: =C21/$D$23 -> 0.92655367 | I21: Inisialisasi
A22: 11 | B22: =Data!B15 -> 44652 | C22: =Data!D15 -> 346 | F22: =C22/$D$23 -> 1.3032015 | I22: Inisialisasi
A23: 12 | B23: =Data!B16 -> 44682 | C23: =Data!D16 -> 289 | D23: =AVERAGE(C12:C23) -> 265.5 | E23: =(AVERAGE(C24:C35)-AVERAGE(C12:C23))/$B$6 -> 0.84027778 | F23: =C23/$D$23 -> 1.0885122 | I23: Inisialisasi
A24: 13 | B24: =Data!B17 -> 44713 | C24: =Data!D17 -> 251 | D24: =$B$3*(C24/F12)+(1-$B$3)*(D23+E23) -> 266.57429 | E24: =$B$4*(D24-D23)+(1-$B$4)*E23 -> 0.90814075 | F24: =$B$5*(C24/D24)+(1-$B$5)*F12 -> 0.92651895 | G24: =(D23+E23)*F12 -> 230.72792 | H24: =ABS(C24-G24)/C24 -> 0.080765242 | I24: Smoothing
A25: 14 | B25: =Data!B18 -> 44743 | C25: =Data!D18 -> 277 | D25: =$B$3*(C25/F13)+(1-$B$3)*(D24+E24) -> 267.55176 | E25: =$B$4*(D25-D24)+(1-$B$4)*E24 -> 0.92824824 | F25: =$B$5*(C25/D25)+(1-$B$5)*F13 -> 1.0301342 | G25: =(D24+E24)*F13 -> 270.0011 | H25: =ABS(C25-G25)/C25 -> 0.025266802 | I25: Smoothing
A26: 15 | B26: =Data!B19 -> 44774 | C26: =Data!D19 -> 256 | D26: =$B$3*(C26/F14)+(1-$B$3)*(D25+E25) -> 268.88467 | E26: =$B$4*(D26-D25)+(1-$B$4)*E25 -> 1.045598 | F26: =$B$5*(C26/D26)+(1-$B$5)*F14 -> 0.9273899 | G26: =(D25+E25)*F14 -> 222.46931 | H26: =ABS(C26-G26)/C26 -> 0.13097924 | I26: Smoothing
A27: 16 | B27: =Data!B20 -> 44805 | C27: =Data!D20 -> 247 | D27: =$B$3*(C27/F15)+(1-$B$3)*(D26+E26) -> 269.75321 | E27: =$B$4*(D27-D26)+(1-$B$4)*E26 -> 0.99425275 | F27: =$B$5*(C27/D27)+(1-$B$5)*F15 -> 0.92837827 | G27: =(D26+E26)*F15 -> 264.33849 | H27: =ABS(C27-G27)/C27 -> 0.070196315 | I27: Smoothing
A28: 17 | B28: =Data!B21 -> 44835 | C28: =Data!D21 -> 250 | D28: =$B$3*(C28/F16)+(1-$B$3)*(D27+E27) -> 270.67392 | E28: =$B$4*(D28-D27)+(1-$B$4)*E27 -> 0.97292439 | F28: =$B$5*(C28/D28)+(1-$B$5)*F16 -> 0.92872696 | G28: =(D27+E27)*F16 -> 256.98065 | H28: =ABS(C28-G28)/C28 -> 0.027922582 | I28: Smoothing
A29: 18 | B29: =Data!B22 -> 44866 | C29: =Data!D22 -> 264 | D29: =$B$3*(C29/F17)+(1-$B$3)*(D28+E28) -> 271.83876 | E29: =$B$4*(D29-D28)+(1-$B$4)*E28 -> 1.0285792 | F29: =$B$5*(C29/D29)+(1-$B$5)*F17 -> 0.95847541 | G29: =(D28+E28)*F17 -> 246.57962 | H29: =ABS(C29-G29)/C29 -> 0.065986284 | I29: Smoothing
A30: 19 | B30: =Data!B23 -> 44896 | C30: =Data!D23 -> 320 | D30: =$B$3*(C30/F18)+(1-$B$3)*(D29+E29) -> 272.95191 | E30: =$B$4*(D30-D29)+(1-$B$4)*E29 -> 1.053105 | F30: =$B$5*(C30/D30)+(1-$B$5)*F18 -> 1.1653894 | G30: =(D29+E29)*F18 -> 310.38017 | H30: =ABS(C30-G30)/C30 -> 0.030061963 | I30: Smoothing
A31: 20 | B31: =Data!B24 -> 44927 | C31: =Data!D24 -> 278 | D31: =$B$3*(C31/F19)+(1-$B$3)*(D30+E30) -> 273.82778 | E31: =$B$4*(D31-D30)+(1-$B$4)*E30 -> 1.0017061 | F31: =$B$5*(C31/D31)+(1-$B$5)*F19 -> 1.0291385 | G31: =(D30+E30)*F19 -> 297.22578 | H31: =ABS(C31-G31)/C31 -> 0.069157472 | I31: Smoothing
A32: 21 | B32: =Data!B25 -> 44958 | C32: =Data!D25 -> 254 | D32: =$B$3*(C32/F20)+(1-$B$3)*(D31+E31) -> 274.845 | E32: =$B$4*(D32-D31)+(1-$B$4)*E31 -> 1.0062059 | F32: =$B$5*(C32/D32)+(1-$B$5)*F20 -> 0.92312995 | G32: =(D31+E31)*F20 -> 252.57399 | H32: =ABS(C32-G32)/C32 -> 0.0056142244 | I32: Smoothing
A33: 22 | B33: =Data!B26 -> 44986 | C33: =Data!D26 -> 297 | D33: =$B$3*(C33/F21)+(1-$B$3)*(D32+E32) -> 276.29812 | E33: =$B$4*(D33-D32)+(1-$B$4)*E32 -> 1.1358112 | F33: =$B$5*(C33/D33)+(1-$B$5)*F21 -> 1.0452514 | G33: =(D32+E32)*F21 -> 255.59095 | H33: =ABS(C33-G33)/C33 -> 0.13942442 | I33: Smoothing
A34: 23 | B34: =Data!B27 -> 45017 | C34: =Data!D27 -> 352 | D34: =$B$3*(C34/F22)+(1-$B$3)*(D33+E33) -> 277.36063 | E34: =$B$4*(D34-D33)+(1-$B$4)*E33 -> 1.1145546 | F34: =$B$5*(C34/D34)+(1-$B$5)*F22 -> 1.275925 | G34: =(D33+E33)*F22 -> 361.55232 | H34: =ABS(C34-G34)/C34 -> 0.027137261 | I34: Smoothing
A35: 24 | B35: =Data!B28 -> 45047 | C35: =Data!D28 -> 261 | D35: =$B$3*(C35/F23)+(1-$B$3)*(D34+E34) -> 278.0882 | E35: =$B$4*(D35-D34)+(1-$B$4)*E34 -> 1.0023293 | F35: =$B$5*(C35/D35)+(1-$B$5)*F23 -> 0.96854336 | G35: =(D34+E34)*F23 -> 303.12365 | H35: =ABS(C35-G35)/C35 -> 0.16139329 | I35: Smoothing
... A71: 60 | B71: =Data!B64 -> 46143 | C71: =Data!D64 -> 295 | D71: =$B$3*(C71/F59)+(1-$B$3)*(D70+E70) -> 327.65597 | E71: =$B$4*(D71-D70)+(1-$B$4)*E70 -> 1.457198 | F71: =$B$5*(C71/D71)+(1-$B$5)*F59 -> 0.90334453 | G71: =(D70+E70)*F59 -> 299.98093 | H71: =ABS(C71-G71)/C71 -> 0.016884502 | I71: Smoothing
A72: 61 | B72: =EDATE(B71,1) -> 46174 | G72: =($D$71+(A72-60)*$E$71)*F60 -> 341.125 | I72: Ramalan
A73: 62 | B73: =EDATE(B72,1) -> 46204 | G73: =($D$71+(A73-60)*$E$71)*F61 -> 386.0402 | I73: Ramalan
A74: 63 | B74: =EDATE(B73,1) -> 46235 | G74: =($D$71+(A74-60)*$E$71)*F62 -> 331.63378 | I74: Ramalan
A75: 64 | B75: =EDATE(B74,1) -> 46266 | G75: =($D$71+(A75-60)*$E$71)*F63 -> 324.53001 | I75: Ramalan
A76: 65 | B76: =EDATE(B75,1) -> 46296 | G76: =($D$71+(A76-60)*$E$71)*F64 -> 303.79482 | I76: Ramalan
A77: 66 | B77: =EDATE(B76,1) -> 46327 | G77: =($D$71+(A77-60)*$E$71)*F65 -> 324.53717 | I77: Ramalan
...

Sheet TES_MieGoreng_Uji
A1: TRIPLE EXPONENTIAL SMOOTHING (Holt-Winters multiplikatif) - Mie Goreng Spesial - UJI (latih t=1..48, uji t=49..60)
A3: alpha (level) | B3: 0.01 | C3: alpha/beta/gamma = hasil optimasi SSE (Python, L-BFGS-B, batas 0,01-0,99) pada data latih t=1..48, dibulatkan 2 desimal. Bisa diganti manual; di Excel bisa dioptimasi dengan Solver pada B9.
A4: beta (tren) | B4: 0.01 | C4: Inisialisasi: L12 = rata-rata musim 1; b12 = (rata-rata musim 2 - rata-rata musim 1)/m; S_t = Y_t/L12 (t=1..12).
A5: gamma (musiman) | B5: 0.99 | C5: F_t=(L_(t-1)+b_(t-1))*S_(t-m); L_t=a*Y_t/S_(t-m)+(1-a)(L_(t-1)+b_(t-1)); b_t=b(L_t-L_(t-1))+(1-b)b_(t-1); S_t=g*Y_t/L_t+(1-g)S_(t-m).
A6: m (panjang musim) | B6: 12 | C6: Ramalan: F_(n+h) = (L_n + h*b_n)*S_(n+h-m), n=48. Baris ramalan dibandingkan dengan aktual (holdout).
A7: MAPE holdout (t=49..60) | B7: =AVERAGE(H60:H71) -> 0.085236323
A8: MAPE in-sample (t=13..48) | B8: =AVERAGE(H24:H59) -> 0.052046581
A9: SSE in-sample (t=13..48) | B9: =SUMXMY2(C24:C59,G24:G59) -> 11571.017
A11: t | B11: Periode | C11: Aktual (Y) | D11: Level (L) | E11: Tren (b) | F11: Musiman (S) | G11: Fitted / Ramalan | H11: APE | I11: Tahap
A12: 1 | B12: =Data!B5 -> 44348 | C12: =Data!E5 -> 221 | F12: =C12/$D$23 -> 0.95053763 | I12: Inisialisasi
A13: 2 | B13: =Data!B6 -> 44378 | C13: =Data!E6 -> 238 | F13: =C13/$D$23 -> 1.0236559 | I13: Inisialisasi
A14: 3 | B14: =Data!B7 -> 44409 | C14: =Data!E7 -> 222 | F14: =C14/$D$23 -> 0.95483871 | I14: Inisialisasi
A15: 4 | B15: =Data!B8 -> 44440 | C15: =Data!E8 -> 204 | F15: =C15/$D$23 -> 0.87741935 | I15: Inisialisasi
A16: 5 | B16: =Data!B9 -> 44470 | C16: =Data!E9 -> 221 | F16: =C16/$D$23 -> 0.95053763 | I16: Inisialisasi
A17: 6 | B17: =Data!B10 -> 44501 | C17: =Data!E10 -> 225 | F17: =C17/$D$23 -> 0.96774194 | I17: Inisialisasi
A18: 7 | B18: =Data!B11 -> 44531 | C18: =Data!E11 -> 278 | F18: =C18/$D$23 -> 1.1956989 | I18: Inisialisasi
A19: 8 | B19: =Data!B12 -> 44562 | C19: =Data!E12 -> 245 | F19: =C19/$D$23 -> 1.0537634 | I19: Inisialisasi
A20: 9 | B20: =Data!B13 -> 44593 | C20: =Data!E13 -> 179 | F20: =C20/$D$23 -> 0.76989247 | I20: Inisialisasi
A21: 10 | B21: =Data!B14 -> 44621 | C21: =Data!E14 -> 223 | F21: =C21/$D$23 -> 0.95913978 | I21: Inisialisasi
A22: 11 | B22: =Data!B15 -> 44652 | C22: =Data!E15 -> 293 | F22: =C22/$D$23 -> 1.2602151 | I22: Inisialisasi
A23: 12 | B23: =Data!B16 -> 44682 | C23: =Data!E16 -> 241 | D23: =AVERAGE(C12:C23) -> 232.5 | E23: =(AVERAGE(C24:C35)-AVERAGE(C12:C23))/$B$6 -> 0.80555556 | F23: =C23/$D$23 -> 1.0365591 | I23: Inisialisasi
A24: 13 | B24: =Data!B17 -> 44713 | C24: =Data!E17 -> 228 | D24: =$B$3*(C24/F12)+(1-$B$3)*(D23+E23) -> 233.37114 | E24: =$B$4*(D24-D23)+(1-$B$4)*E23 -> 0.80621143 | F24: =$B$5*(C24/D24)+(1-$B$5)*F12 -> 0.97672008 | G24: =(D23+E23)*F12 -> 221.76571 | H24: =ABS(C24-G24)/C24 -> 0.027343373 | I24: Smoothing
A25: 14 | B25: =Data!B18 -> 44743 | C25: =Data!E18 -> 245 | D25: =$B$3*(C25/F13)+(1-$B$3)*(D24+E24) -> 234.22896 | E25: =$B$4*(D25-D24)+(1-$B$4)*E24 -> 0.80672751 | F25: =$B$5*(C25/D25)+(1-$B$5)*F13 -> 1.0457618 | G25: =(D24+E24)*F13 -> 239.71703 | H25: =ABS(C25-G25)/C25 -> 0.021563129 | I25: Smoothing
A26: 15 | B26: =Data!B19 -> 44774 | C26: =Data!E19 -> 223 | D26: =$B$3*(C26/F14)+(1-$B$3)*(D25+E25) -> 235.02081 | E26: =$B$4*(D26-D25)+(1-$B$4)*E25 -> 0.80657867 | F26: =$B$5*(C26/D26)+(1-$B$5)*F14 -> 0.94891203 | G26: =(D25+E25)*F14 -> 224.42118 | H26: =ABS(C26-G26)/C26 -> 0.0063729831 | I26: Smoothing
A27: 16 | B27: =Data!B20 -> 44805 | C27: =Data!E20 -> 206 | D27: =$B$3*(C27/F15)+(1-$B$3)*(D26+E26) -> 235.81691 | E27: =$B$4*(D27-D26)+(1-$B$4)*E26 -> 0.80647388 | F27: =$B$5*(C27/D27)+(1-$B$5)*F15 -> 0.87359769 | G27: =(D26+E26)*F15 -> 206.91951 | H27: =ABS(C27-G27)/C27 -> 0.0044636506 | I27: Smoothing
A28: 17 | B28: =Data!B21 -> 44835 | C28: =Data!E21 -> 207 | D28: =$B$3*(C28/F16)+(1-$B$3)*(D27+E27) -> 236.43486 | E28: =$B$4*(D28-D27)+(1-$B$4)*E27 -> 0.80458869 | F28: =$B$5*(C28/D28)+(1-$B$5)*F16 -> 0.87625574 | G28: =(D27+E27)*F16 -> 224.91943 | H28: =ABS(C28-G28)/C28 -> 0.086567281 | I28: Smoothing
A29: 18 | B29: =Data!B22 -> 44866 | C29: =Data!E22 -> 228 | D29: =$B$3*(C29/F17)+(1-$B$3)*(D28+E28) -> 237.22305 | E29: =$B$4*(D29-D28)+(1-$B$4)*E28 -> 0.80442474 | F29: =$B$5*(C29/D29)+(1-$B$5)*F17 -> 0.96118696 | G29: =(D28+E28)*F17 -> 229.58656 | H29: =ABS(C29-G29)/C29 -> 0.0069586121 | I29: Smoothing
A30: 19 | B30: =Data!B23 -> 44896 | C30: =Data!E23 -> 282 | D30: =$B$3*(C30/F18)+(1-$B$3)*(D29+E29) -> 238.00566 | E30: =$B$4*(D30-D29)+(1-$B$4)*E29 -> 0.80420653 | F30: =$B$5*(C30/D30)+(1-$B$5)*F18 -> 1.1849543 | G30: =(D29+E29)*F18 -> 284.6092 | H30: =ABS(C30-G30)/C30 -> 0.0092524858 | I30: Smoothing
A31: 20 | B31: =Data!B24 -> 44927 | C31: =Data!E24 -> 261 | D31: =$B$3*(C31/F19)+(1-$B$3)*(D30+E30) -> 238.8986 | E31: =$B$4*(D31-D30)+(1-$B$4)*E30 -> 0.80509391 | F31: =$B$5*(C31/D31)+(1-$B$5)*F19 -> 1.0921262 | G31: =(D30+E30)*F19 -> 251.6491 | H31: =ABS(C31-G31)/C31 -> 0.035827187 | I31: Smoothing
A32: 21 | B32: =Data!B25 -> 44958 | C32: =Data!E25 -> 228 | D32: =$B$3*(C32/F20)+(1-$B$3)*(D31+E31) -> 240.26811 | E32: =$B$4*(D32-D31)+(1-$B$4)*E31 -> 0.81073806 | F32: =$B$5*(C32/D32)+(1-$B$5)*F20 -> 0.94714943 | G32: =(D31+E31)*F20 -> 184.54607 | H32: =ABS(C32-G32)/C32 -> 0.19058741 | I32: Smoothing
A33: 22 | B33: =Data!B26 -> 44986 | C33: =Data!E26 -> 256 | D33: =$B$3*(C33/F21)+(1-$B$3)*(D32+E32) -> 241.33712 | E33: =$B$4*(D33-D32)+(1-$B$4)*E32 -> 0.81332076 | F33: =$B$5*(C33/D33)+(1-$B$5)*F21 -> 1.0597407 | G33: =(D32+E32)*F21 -> 231.22832 | H33: =ABS(C33-G33)/C33 -> 0.09676439 | I33: Smoothing
A34: 23 | B34: =Data!B27 -> 45017 | C34: =Data!E27 -> 311 | D34: =$B$3*(C34/F22)+(1-$B$3)*(D33+E33) -> 242.19677 | E34: =$B$4*(D34-D33)+(1-$B$4)*E33 -> 0.81378405 | F34: =$B$5*(C34/D34)+(1-$B$5)*F22 -> 1.2838412 | G34: =(D33+E33)*F22 -> 305.16163 | H34: =ABS(C34-G34)/C34 -> 0.018772893 | I34: Smoothing
A35: 24 | B35: =Data!B28 -> 45047 | C35: =Data!E28 -> 231 | D35: =$B$3*(C35/F23)+(1-$B$3)*(D34+E34) -> 242.80897 | E35: =$B$4*(D35-D34)+(1-$B$4)*E34 -> 0.81176826 | F35: =$B$5*(C35/D35)+(1-$B$5)*F23 -> 0.95221711 | G35: =(D34+E34)*F23 -> 251.89481 | H35: =ABS(C35-G35)/C35 -> 0.090453721 | I35: Smoothing
... A59: 48 | B59: =Data!B52 -> 45778 | C59: =Data!E52 -> 243 | D59: =$B$3*(C59/F47)+(1-$B$3)*(D58+E58) -> 261.88264 | E59: =$B$4*(D59-D58)+(1-$B$4)*E58 -> 0.80737217 | F59: =$B$5*(C59/D59)+(1-$B$5)*F47 -> 0.92813931 | G59: =(D58+E58)*F47 -> 249.42191 | H59: =ABS(C59-G59)/C59 -> 0.026427605 | I59: Smoothing
A60: 49 | B60: =EDATE(B59,1) -> 45809 | C60: =Data!E53 -> 239 | G60: =($D$59+(A60-48)*$E$59)*F48 -> 241.2462 | H60: =ABS(C60-G60)/C60 -> 0.0093983232 | I60: Ramalan (holdout)
A61: 50 | B61: =EDATE(B60,1) -> 45839 | C61: =Data!E54 -> 277 | G61: =($D$59+(A61-48)*$E$59)*F49 -> 267.35743 | H61: =ABS(C61-G61)/C61 -> 0.03481074 | I61: Ramalan (holdout)
A62: 51 | B62: =EDATE(B61,1) -> 45870 | C62: =Data!E55 -> 252 | G62: =($D$59+(A62-48)*$E$59)*F50 -> 233.16811 | H62: =ABS(C62-G62)/C62 -> 0.074729736 | I62: Ramalan (holdout)
A63: 52 | B63: =EDATE(B62,1) -> 45901 | C63: =Data!E56 -> 278 | G63: =($D$59+(A63-48)*$E$59)*F51 -> 239.64528 | H63: =ABS(C63-G63)/C63 -> 0.13796663 | I63: Ramalan (holdout)
A64: 53 | B64: =EDATE(B63,1) -> 45931 | C64: =Data!E57 -> 278 | G64: =($D$59+(A64-48)*$E$59)*F52 -> 235.70903 | H64: =ABS(C64-G64)/C64 -> 0.1521258 | I64: Ramalan (holdout)
A65: 54 | B65: =EDATE(B64,1) -> 45962 | C65: =Data!E58 -> 278 | G65: =($D$59+(A65-48)*$E$59)*F53 -> 248.00784 | H65: =ABS(C65-G65)/C65 -> 0.10788547 | I65: Ramalan (holdout)
...

Sheet TES_MieGoreng
A1: TRIPLE EXPONENTIAL SMOOTHING (Holt-Winters multiplikatif) - Mie Goreng Spesial - FINAL (latih semua 60 bulan, ramal 12 bulan ke depan)
A3: alpha (level) | B3: 0.14 | C3: alpha/beta/gamma = hasil optimasi SSE (Python, L-BFGS-B, batas 0,01-0,99) pada data latih t=1..60, dibulatkan 2 desimal. Bisa diganti manual; di Excel bisa dioptimasi dengan Solver pada B9.
A4: beta (tren) | B4: 0.01 | C4: Inisialisasi: L12 = rata-rata musim 1; b12 = (rata-rata musim 2 - rata-rata musim 1)/m; S_t = Y_t/L12 (t=1..12).
A5: gamma (musiman) | B5: 0.99 | C5: F_t=(L_(t-1)+b_(t-1))*S_(t-m); L_t=a*Y_t/S_(t-m)+(1-a)(L_(t-1)+b_(t-1)); b_t=b(L_t-L_(t-1))+(1-b)b_(t-1); S_t=g*Y_t/L_t+(1-g)S_(t-m).
A6: m (panjang musim) | B6: 12 | C6: Ramalan: F_(n+h) = (L_n + h*b_n)*S_(n+h-m), n=60.
A7: MAPE holdout | B7: n/a (lihat sheet _Uji)
A8: MAPE in-sample (t=13..60) | B8: =AVERAGE(H24:H71) -> 0.057760899
A9: SSE in-sample (t=13..60) | B9: =SUMXMY2(C24:C71,G24:G71) -> 18838.16
A11: t | B11: Periode | C11: Aktual (Y) | D11: Level (L) | E11: Tren (b) | F11: Musiman (S) | G11: Fitted / Ramalan | H11: APE | I11: Tahap
A12: 1 | B12: =Data!B5 -> 44348 | C12: =Data!E5 -> 221 | F12: =C12/$D$23 -> 0.95053763 | I12: Inisialisasi
A13: 2 | B13: =Data!B6 -> 44378 | C13: =Data!E6 -> 238 | F13: =C13/$D$23 -> 1.0236559 | I13: Inisialisasi
A14: 3 | B14: =Data!B7 -> 44409 | C14: =Data!E7 -> 222 | F14: =C14/$D$23 -> 0.95483871 | I14: Inisialisasi
A15: 4 | B15: =Data!B8 -> 44440 | C15: =Data!E8 -> 204 | F15: =C15/$D$23 -> 0.87741935 | I15: Inisialisasi
A16: 5 | B16: =Data!B9 -> 44470 | C16: =Data!E9 -> 221 | F16: =C16/$D$23 -> 0.95053763 | I16: Inisialisasi
A17: 6 | B17: =Data!B10 -> 44501 | C17: =Data!E10 -> 225 | F17: =C17/$D$23 -> 0.96774194 | I17: Inisialisasi
A18: 7 | B18: =Data!B11 -> 44531 | C18: =Data!E11 -> 278 | F18: =C18/$D$23 -> 1.1956989 | I18: Inisialisasi
A19: 8 | B19: =Data!B12 -> 44562 | C19: =Data!E12 -> 245 | F19: =C19/$D$23 -> 1.0537634 | I19: Inisialisasi
A20: 9 | B20: =Data!B13 -> 44593 | C20: =Data!E13 -> 179 | F20: =C20/$D$23 -> 0.76989247 | I20: Inisialisasi
A21: 10 | B21: =Data!B14 -> 44621 | C21: =Data!E14 -> 223 | F21: =C21/$D$23 -> 0.95913978 | I21: Inisialisasi
A22: 11 | B22: =Data!B15 -> 44652 | C22: =Data!E15 -> 293 | F22: =C22/$D$23 -> 1.2602151 | I22: Inisialisasi
A23: 12 | B23: =Data!B16 -> 44682 | C23: =Data!E16 -> 241 | D23: =AVERAGE(C12:C23) -> 232.5 | E23: =(AVERAGE(C24:C35)-AVERAGE(C12:C23))/$B$6 -> 0.80555556 | F23: =C23/$D$23 -> 1.0365591 | I23: Inisialisasi
A24: 13 | B24: =Data!B17 -> 44713 | C24: =Data!E17 -> 228 | D24: =$B$3*(C24/F12)+(1-$B$3)*(D23+E23) -> 234.22377 | E24: =$B$4*(D24-D23)+(1-$B$4)*E23 -> 0.81473773 | F24: =$B$5*(C24/D24)+(1-$B$5)*F12 -> 0.97319918 | G24: =(D23+E23)*F12 -> 221.76571 | H24: =ABS(C24-G24)/C24 -> 0.027343373 | I24: Smoothing
A25: 14 | B25: =Data!B18 -> 44743 | C25: =Data!E18 -> 245 | D25: =$B$3*(C25/F13)+(1-$B$3)*(D24+E24) -> 235.64047 | E25: =$B$4*(D25-D24)+(1-$B$4)*E24 -> 0.82075735 | F25: =$B$5*(C25/D25)+(1-$B$5)*F13 -> 1.0395589 | G25: =(D24+E24)*F13 -> 240.59856 | H25: =ABS(C25-G25)/C25 -> 0.017965054 | I25: Smoothing
A26: 15 | B26: =Data!B19 -> 44774 | C26: =Data!E19 -> 223 | D26: =$B$3*(C26/F14)+(1-$B$3)*(D25+E25) -> 236.05328 | E26: =$B$4*(D26-D25)+(1-$B$4)*E25 -> 0.81667784 | F26: =$B$5*(C26/D26)+(1-$B$5)*F14 -> 0.94480335 | G26: =(D25+E25)*F14 -> 225.78234 | H26: =ABS(C26-G26)/C26 -> 0.012476841 | I26: Smoothing
A27: 16 | B27: =Data!B20 -> 44805 | C27: =Data!E20 -> 206 | D27: =$B$3*(C27/F15)+(1-$B$3)*(D26+E26) -> 236.57728 | E27: =$B$4*(D27-D26)+(1-$B$4)*E26 -> 0.81375108 | F27: =$B$5*(C27/D27)+(1-$B$5)*F15 -> 0.87081809 | G27: =(D26+E26)*F15 -> 207.83428 | H27: =ABS(C27-G27)/C27 -> 0.0089042955 | I27: Smoothing
A28: 17 | B28: =Data!B21 -> 44835 | C28: =Data!E21 -> 207 | D28: =$B$3*(C28/F16)+(1-$B$3)*(D27+E27) -> 234.6443 | E28: =$B$4*(D28-D27)+(1-$B$4)*E27 -> 0.78628372 | F28: =$B$5*(C28/D28)+(1-$B$5)*F16 -> 0.88286988 | G28: =(D27+E27)*F16 -> 225.64911 | H28: =ABS(C28-G28)/C28 -> 0.090092318 | I28: Smoothing
A29: 18 | B29: =Data!B22 -> 44866 | C29: =Data!E22 -> 228 | D29: =$B$3*(C29/F17)+(1-$B$3)*(D28+E28) -> 235.4543 | E29: =$B$4*(D29-D28)+(1-$B$4)*E28 -> 0.78652091 | F29: =$B$5*(C29/D29)+(1-$B$5)*F17 -> 0.96833479 | G29: =(D28+E28)*F17 -> 227.83605 | H29: =ABS(C29-G29)/C29 -> 0.00071909975 | I29: Smoothing
A30: 19 | B30: =Data!B23 -> 44896 | C30: =Data!E23 -> 282 | D30: =$B$3*(C30/F18)+(1-$B$3)*(D29+E29) -> 236.18545 | E30: =$B$4*(D30-D29)+(1-$B$4)*E29 -> 0.78596722 | F30: =$B$5*(C30/D30)+(1-$B$5)*F18 -> 1.1939942 | G30: =(D29+E29)*F18 -> 282.47289 | H30: =ABS(C30-G30)/C30 -> 0.0016769298 | I30: Smoothing
A31: 20 | B31: =Data!B24 -> 44927 | C31: =Data!E24 -> 261 | D31: =$B$3*(C31/F19)+(1-$B$3)*(D30+E30) -> 238.47113 | E31: =$B$4*(D31-D30)+(1-$B$4)*E30 -> 0.80096438 | F31: =$B$5*(C31/D31)+(1-$B$5)*F19 -> 1.094065 | G31: =(D30+E30)*F19 -> 249.71182 | H31: =ABS(C31-G31)/C31 -> 0.043249746 | I31: Smoothing
A32: 21 | B32: =Data!B25 -> 44958 | C32: =Data!E25 -> 228 | D32: =$B$3*(C32/F20)+(1-$B$3)*(D31+E31) -> 247.23434 | E32: =$B$4*(D32-D31)+(1-$B$4)*E31 -> 0.88058679 | F32: =$B$5*(C32/D32)+(1-$B$5)*F20 -> 0.9206789 | G32: =(D31+E31)*F20 -> 184.21379 | H32: =ABS(C32-G32)/C32 -> 0.19204479 | I32: Smoothing
A33: 22 | B33: =Data!B26 -> 44986 | C33: =Data!E26 -> 256 | D33: =$B$3*(C33/F21)+(1-$B$3)*(D32+E32) -> 250.74565 | E33: =$B$4*(D33-D32)+(1-$B$4)*E32 -> 0.90689406 | F33: =$B$5*(C33/D33)+(1-$B$5)*F21 -> 1.0203367 | G33: =(D32+E32)*F21 -> 237.9769 | H33: =ABS(C33-G33)/C33 -> 0.070402747 | I33: Smoothing
A34: 23 | B34: =Data!B27 -> 45017 | C34: =Data!E27 -> 311 | D34: =$B$3*(C34/F22)+(1-$B$3)*(D33+E33) -> 250.97085 | E34: =$B$4*(D34-D33)+(1-$B$4)*E33 -> 0.90007708 | F34: =$B$5*(C34/D34)+(1-$B$5)*F22 -> 1.239398 | G34: =(D33+E33)*F22 -> 317.13633 | H34: =ABS(C34-G34)/C34 -> 0.019730957 | I34: Smoothing
A35: 24 | B35: =Data!B28 -> 45047 | C35: =Data!E28 -> 231 | D35: =$B$3*(C35/F23)+(1-$B$3)*(D34+E34) -> 247.80837 | E35: =$B$4*(D35-D34)+(1-$B$4)*E34 -> 0.85945156 | F35: =$B$5*(C35/D35)+(1-$B$5)*F23 -> 0.93321576 | G35: =(D34+E34)*F23 -> 261.07911 | H35: =ABS(C35-G35)/C35 -> 0.1302126 | I35: Smoothing
... A71: 60 | B71: =Data!B64 -> 46143 | C71: =Data!E64 -> 294 | D71: =$B$3*(C71/F59)+(1-$B$3)*(D70+E70) -> 293.80709 | E71: =$B$4*(D71-D70)+(1-$B$4)*E70 -> 1.0060793 | F71: =$B$5*(C71/D71)+(1-$B$5)*F59 -> 0.99985653 | G71: =(D70+E70)*F59 -> 266.66722 | H71: =ABS(C71-G71)/C71 -> 0.092968627 | I71: Smoothing
A72: 61 | B72: =EDATE(B71,1) -> 46174 | G72: =($D$71+(A72-60)*$E$71)*F60 -> 266.11819 | I72: Ramalan
A73: 62 | B73: =EDATE(B72,1) -> 46204 | G73: =($D$71+(A73-60)*$E$71)*F61 -> 306.86205 | I73: Ramalan
A74: 63 | B74: =EDATE(B73,1) -> 46235 | G74: =($D$71+(A74-60)*$E$71)*F62 -> 276.44914 | I74: Ramalan
A75: 64 | B75: =EDATE(B74,1) -> 46266 | G75: =($D$71+(A75-60)*$E$71)*F63 -> 299.47487 | I75: Ramalan
A76: 65 | B76: =EDATE(B75,1) -> 46296 | G76: =($D$71+(A76-60)*$E$71)*F64 -> 294.54847 | I76: Ramalan
A77: 66 | B77: =EDATE(B76,1) -> 46327 | G77: =($D$71+(A77-60)*$E$71)*F65 -> 292.66506 | I77: Ramalan
...

Sheet Census_NasiGoreng_Uji
A1: DEKOMPOSISI CENSUS II (X-11 sederhana, multiplikatif) - Nasi Goreng Spesial - UJI (latih t=1..48, uji t=49..60)
A3: Slope tren (per bulan) | B3: =SLOPE(AB18:AB53,A18:A53) -> 1.2410472 | C3: Langkah: (1) tren awal = MA 2x12; (2) SI = Y/tren; (3) musiman awal = filter 3x3 pada SI per bulan kalender, dinormalisasi MA 2x12; (4) Y disesuaikan = Y/S;
A4: Intersep tren | B4: =INTERCEPT(AB18:AB53,A18:A53) -> 255.68425 | C4: (5) tren = Henderson 13 pada Y disesuaikan; (6) ulangi dengan filter 3x5 -> S final & tren final; (7) tren diekstrapolasi linear (SLOPE/INTERCEPT atas tren Henderson).
A5: MAPE holdout (t=49..60) | B5: =AVERAGE(AF60:AF71) -> 0.072807005 | C5: Fitted/Ramalan = tren linear x S final (bulan ke depan memakai S bulan kalender yang sama). Di ujung data, bobot filter yang tidak tersedia dibuang & sisanya dinormalisasi ulang.
A6: t pertama tren tersedia | B6: 7 | C6: Kolom kosong = nilai belum tersedia (tepi data). Bobot filter di sheet Bobot_Filter.
A7: t terakhir tren tersedia | B7: =B8-6 -> 42
A8: n (jumlah data latih) | B8: 48
A9: MAPE in-sample (t=13..48) | B9: =AVERAGE(AF24:AF59) -> 0.041460665
A10: Data | D10: Iterasi 1 (musiman 3x3) | P10: Iterasi 2 (musiman 3x5) & hasil final | AD10: Fitted / Ramalan
A11: t | B11: Periode | C11: Y | D11: T1: MA 2x12 | E11: SI1 = Y/T1 | F11: SI1 t-24 | G11: SI1 t-12 | H11: SI1 t | I11: SI1 t+12 | J11: SI1 t+24 | K11: S1 mentah (3x3) | L11: MA 2x12 dari S1 | M11: S1 (dinormalisasi) | N11: A1 = Y/S1 | O11: T2: Henderson 13 | P11: SI2 = Y/T2 | Q11: SI2 t-36 | R11: SI2 t-24 | S11: SI2 t-12 | T11: SI2 t | U11: SI2 t+12 | V11: SI2 t+24 | W11: SI2 t+36 | X11: S2 mentah (3x5) | Y11: MA 2x12 dari S2 | Z11: S2 final | AA11: A2 = Y/S2 | AB11: T3: tren final (Henderson 13) | AC11: I = A2/T3 | AD11: Tren linear | AE11: Fitted / Ramalan | AF11: APE
A12: 1 | B12: =Data!B5 -> 44348 | C12: =Data!D5 -> 230 | D12: =IF(AND($A12>=$B$6,$A12<=$B$7),SUMPRODUCT(Bobot_Filter!$B$4:$B$16,C6:C18),"") | E12: =IF(ISNUMBER(D12),C12/D12,"") | F12: =IF(AND($A12+(-24)>=1,$A12+(-24)<=$B$8),INDEX($E$12:$E$59,$A12+(-24)),"") | G12: =IF(AND($A12+(-12)>=1,$A12+(-12)<=$B$8),INDEX($E$12:$E$59,$A12+(-12)),"") | H12: =IF(AND($A12+(0)>=1,$A12+(0)<=$B$8),INDEX($E$12:$E$59,$A12+(0)),"") | I12: =IF(AND($A12+(12)>=1,$A12+(12)<=$B$8),INDEX($E$12:$E$59,$A12+(12)),"") -> 0.92138269 | J12: =IF(AND($A12+(24)>=1,$A12+(24)<=$B$8),INDEX($E$12:$E$59,$A12+(24)),"") -> 0.95452552 | K12: =IF(SUMPRODUCT(Bobot_Filter!$B$38:$F$38,ISNUMBER(F12:J12)*1)>0,SUMPRODUCT(Bobot_Filter!$B$38:$F$38,F12:J12)/SUMPRODUCT(Bobot_Filter!$B$38:$F$38,ISNUMBER(F12:J12)*1),"") -> 0.9324303 | L12: =IF(AND($A12>=$B$6,$A12<=$B$7),SUMPRODUCT(Bobot_Filter!$B$4:$B$16,K6:K18),"") | M12: =K12/INDEX($L$12:$L$59,MAX($B$6,MIN($A12,$B$7))) -> 0.93344844 | N12: =C12/M12 -> 246.39818 | O12: =IF(AND($A12>=$B$6,$A12<=$B$7),SUMPRODUCT(Bobot_Filter!$B$20:$B$32,N6:N18),"") | P12: =IF(ISNUMBER(O12),C12/O12,"") | Q12: =IF(AND($A12+(-36)>=1,$A12+(-36)<=$B$8),INDEX($P$12:$P$59,$A12+(-36)),"") | R12: =IF(AND($A12+(-24)>=1,$A12+(-24)<=$B$8),INDEX($P$12:$P$59,$A12+(-24)),"") | S12: =IF(AND($A12+(-12)>=1,$A12+(-12)<=$B$8),INDEX($P$12:$P$59,$A12+(-12)),"") | T12: =IF(AND($A12+(0)>=1,$A12+(0)<=$B$8),INDEX($P$12:$P$59,$A12+(0)),"") | U12: =IF(AND($A12+(12)>=1,$A12+(12)<=$B$8),INDEX($P$12:$P$59,$A12+(12)),"") -> 0.91881937 | V12: =IF(AND($A12+(24)>=1,$A12+(24)<=$B$8),INDEX($P$12:$P$59,$A12+(24)),"") -> 0.94164754 | W12: =IF(AND($A12+(36)>=1,$A12+(36)<=$B$8),INDEX($P$12:$P$59,$A12+(36)),"") -> 0.91561325 | X12: =IF(SUMPRODUCT(Bobot_Filter!$B$43:$H$43,ISNUMBER(Q12:W12)*1)>0,SUMPRODUCT(Bobot_Filter!$B$43:$H$43,Q12:W12)/SUMPRODUCT(Bobot_Filter!$B$43:$H$43,ISNUMBER(Q12:W12)*1),"") -> 0.92589441 | Y12: =IF(AND($A12>=$B$6,$A12<=$B$7),SUMPRODUCT(Bobot_Filter!$B$4:$B$16,X6:X18),"") | Z12: =X12/INDEX($Y$12:$Y$59,MAX($B$6,MIN($A12,$B$7))) -> 0.92645376 | AA12: =C12/Z12 -> 248.25848 | AB12: =IF(AND($A12>=$B$6,$A12<=$B$7),SUMPRODUCT(Bobot_Filter!$B$20:$B$32,AA6:AA18),"") | AC12: =IF(ISNUMBER(AB12),AA12/AB12,"") | AD12: =$B$4+$B$3*A12 -> 256.9253 | AE12: =AD12*Z12 -> 238.02941
A13: 2 | B13: =Data!B6 -> 44378 | C13: =Data!D6 -> 268 | D13: =IF(AND($A13>=$B$6,$A13<=$B$7),SUMPRODUCT(Bobot_Filter!$B$4:$B$16,C7:C19),"") | E13: =IF(ISNUMBER(D13),C13/D13,"") | F13: =IF(AND($A13+(-24)>=1,$A13+(-24)<=$B$8),INDEX($E$12:$E$59,$A13+(-24)),"") | G13: =IF(AND($A13+(-12)>=1,$A13+(-12)<=$B$8),INDEX($E$12:$E$59,$A13+(-12)),"") | H13: =IF(AND($A13+(0)>=1,$A13+(0)<=$B$8),INDEX($E$12:$E$59,$A13+(0)),"") | I13: =IF(AND($A13+(12)>=1,$A13+(12)<=$B$8),INDEX($E$12:$E$59,$A13+(12)),"") -> 1.015582 | J13: =IF(AND($A13+(24)>=1,$A13+(24)<=$B$8),INDEX($E$12:$E$59,$A13+(24)),"") -> 1.1105309 | K13: =IF(SUMPRODUCT(Bobot_Filter!$B$38:$F$38,ISNUMBER(F13:J13)*1)>0,SUMPRODUCT(Bobot_Filter!$B$38:$F$38,F13:J13)/SUMPRODUCT(Bobot_Filter!$B$38:$F$38,ISNUMBER(F13:J13)*1),"") -> 1.0472317 | L13: =IF(AND($A13>=$B$6,$A13<=$B$7),SUMPRODUCT(Bobot_Filter!$B$4:$B$16,K7:K19),"") | M13: =K13/INDEX($L$12:$L$59,MAX($B$6,MIN($A13,$B$7))) -> 1.0483752 | N13: =C13/M13 -> 255.63368 | O13: =IF(AND($A13>=$B$6,$A13<=$B$7),SUMPRODUCT(Bobot_Filter!$B$20:$B$32,N7:N19),"") | P13: =IF(ISNUMBER(O13),C13/O13,"") | Q13: =IF(AND($A13+(-36)>=1,$A13+(-36)<=$B$8),INDEX($P$12:$P$59,$A13+(-36)),"") | R13: =IF(AND($A13+(-24)>=1,$A13+(-24)<=$B$8),INDEX($P$12:$P$59,$A13+(-24)),"") | S13: =IF(AND($A13+(-12)>=1,$A13+(-12)<=$B$8),INDEX($P$12:$P$59,$A13+(-12)),"") | T13: =IF(AND($A13+(0)>=1,$A13+(0)<=$B$8),INDEX($P$12:$P$59,$A13+(0)),"") | U13: =IF(AND($A13+(12)>=1,$A13+(12)<=$B$8),INDEX($P$12:$P$59,$A13+(12)),"") -> 1.011107 | V13: =IF(AND($A13+(24)>=1,$A13+(24)<=$B$8),INDEX($P$12:$P$59,$A13+(24)),"") -> 1.0964981 | W13: =IF(AND($A13+(36)>=1,$A13+(36)<=$B$8),INDEX($P$12:$P$59,$A13+(36)),"") -> 1.0059962 | X13: =IF(SUMPRODUCT(Bobot_Filter!$B$43:$H$43,ISNUMBER(Q13:W13)*1)>0,SUMPRODUCT(Bobot_Filter!$B$43:$H$43,Q13:W13)/SUMPRODUCT(Bobot_Filter!$B$43:$H$43,ISNUMBER(Q13:W13)*1),"") -> 1.0387189 | Y13: =IF(AND($A13>=$B$6,$A13<=$B$7),SUMPRODUCT(Bobot_Filter!$B$4:$B$16,X7:X19),"") | Z13: =X13/INDEX($Y$12:$Y$59,MAX($B$6,MIN($A13,$B$7))) -> 1.0393464 | AA13: =C13/Z13 -> 257.85436 | AB13: =IF(AND($A13>=$B$6,$A13<=$B$7),SUMPRODUCT(Bobot_Filter!$B$20:$B$32,AA7:AA19),"") | AC13: =IF(ISNUMBER(AB13),AA13/AB13,"") | AD13: =$B$4+$B$3*A13 -> 258.16635 | AE13: =AD13*Z13 -> 268.32427
A14: 3 | B14: =Data!B7 -> 44409 | C14: =Data!D7 -> 220 | D14: =IF(AND($A14>=$B$6,$A14<=$B$7),SUMPRODUCT(Bobot_Filter!$B$4:$B$16,C8:C20),"") | E14: =IF(ISNUMBER(D14),C14/D14,"") | F14: =IF(AND($A14+(-24)>=1,$A14+(-24)<=$B$8),INDEX($E$12:$E$59,$A14+(-24)),"") | G14: =IF(AND($A14+(-12)>=1,$A14+(-12)<=$B$8),INDEX($E$12:$E$59,$A14+(-12)),"") | H14: =IF(AND($A14+(0)>=1,$A14+(0)<=$B$8),INDEX($E$12:$E$59,$A14+(0)),"") | I14: =IF(AND($A14+(12)>=1,$A14+(12)<=$B$8),INDEX($E$12:$E$59,$A14+(12)),"") -> 0.93858845 | J14: =IF(AND($A14+(24)>=1,$A14+(24)<=$B$8),INDEX($E$12:$E$59,$A14+(24)),"") -> 0.88366762 | K14: =IF(SUMPRODUCT(Bobot_Filter!$B$38:$F$38,ISNUMBER(F14:J14)*1)>0,SUMPRODUCT(Bobot_Filter!$B$38:$F$38,F14:J14)/SUMPRODUCT(Bobot_Filter!$B$38:$F$38,ISNUMBER(F14:J14)*1),"") -> 0.92028151 | L14: =IF(AND($A14>=$B$6,$A14<=$B$7),SUMPRODUCT(Bobot_Filter!$B$4:$B$16,K8:K20),"") | M14: =K14/INDEX($L$12:$L$59,MAX($B$6,MIN($A14,$B$7))) -> 0.92128638 | N14: =C14/M14 -> 238.79654 | O14: =IF(AND($A14>=$B$6,$A14<=$B$7),SUMPRODUCT(Bobot_Filter!$B$20:$B$32,N8:N20),"") | P14: =IF(ISNUMBER(O14),C14/O14,"") | Q14: =IF(AND($A14+(-36)>=1,$A14+(-36)<=$B$8),INDEX($P$12:$P$59,$A14+(-36)),"") | R14: =IF(AND($A14+(-24)>=1,$A14+(-24)<=$B$8),INDEX($P$12:$P$59,$A14+(-24)),"") | S14: =IF(AND($A14+(-12)>=1,$A14+(-12)<=$B$8),INDEX($P$12:$P$59,$A14+(-12)),"") | T14: =IF(AND($A14+(0)>=1,$A14+(0)<=$B$8),INDEX($P$12:$P$59,$A14+(0)),"") | U14: =IF(AND($A14+(12)>=1,$A14+(12)<=$B$8),INDEX($P$12:$P$59,$A14+(12)),"") -> 0.93221933 | V14: =IF(AND($A14+(24)>=1,$A14+(24)<=$B$8),INDEX($P$12:$P$59,$A14+(24)),"") -> 0.88107076 | W14: =IF(AND($A14+(36)>=1,$A14+(36)<=$B$8),INDEX($P$12:$P$59,$A14+(36)),"") -> 0.94820171 | X14: =IF(SUMPRODUCT(Bobot_Filter!$B$43:$H$43,ISNUMBER(Q14:W14)*1)>0,SUMPRODUCT(Bobot_Filter!$B$43:$H$43,Q14:W14)/SUMPRODUCT(Bobot_Filter!$B$43:$H$43,ISNUMBER(Q14:W14)*1),"") -> 0.91783354 | Y14: =IF(AND($A14>=$B$6,$A14<=$B$7),SUMPRODUCT(Bobot_Filter!$B$4:$B$16,X8:X20),"") | Z14: =X14/INDEX($Y$12:$Y$59,MAX($B$6,MIN($A14,$B$7))) -> 0.91838802 | AA14: =C14/Z14 -> 239.55016 | AB14: =IF(AND($A14>=$B$6,$A14<=$B$7),SUMPRODUCT(Bobot_Filter!$B$20:$B$32,AA8:AA20),"") | AC14: =IF(ISNUMBER(AB14),AA14/AB14,"") | AD14: =$B$4+$B$3*A14 -> 259.4074 | AE14: =AD14*Z14 -> 238.23665
A15: 4 | B15: =Data!B8 -> 44440 | C15: =Data!D8 -> 260 | D15: =IF(AND($A15>=$B$6,$A15<=$B$7),SUMPRODUCT(Bobot_Filter!$B$4:$B$16,C9:C21),"") | E15: =IF(ISNUMBER(D15),C15/D15,"") | F15: =IF(AND($A15+(-24)>=1,$A15+(-24)<=$B$8),INDEX($E$12:$E$59,$A15+(-24)),"") | G15: =IF(AND($A15+(-12)>=1,$A15+(-12)<=$B$8),INDEX($E$12:$E$59,$A15+(-12)),"") | H15: =IF(AND($A15+(0)>=1,$A15+(0)<=$B$8),INDEX($E$12:$E$59,$A15+(0)),"") | I15: =IF(AND($A15+(12)>=1,$A15+(12)<=$B$8),INDEX($E$12:$E$59,$A15+(12)),"") -> 0.89723021 | J15: =IF(AND($A15+(24)>=1,$A15+(24)<=$B$8),INDEX($E$12:$E$59,$A15+(24)),"") -> 0.9707255 | K15: =IF(SUMPRODUCT(Bobot_Filter!$B$38:$F$38,ISNUMBER(F15:J15)*1)>0,SUMPRODUCT(Bobot_Filter!$B$38:$F$38,F15:J15)/SUMPRODUCT(Bobot_Filter!$B$38:$F$38,ISNUMBER(F15:J15)*1),"") -> 0.92172864 | L15: =IF(AND($A15>=$B$6,$A15<=$B$7),SUMPRODUCT(Bobot_Filter!$B$4:$B$16,K9:K21),"") | M15: =K15/INDEX($L$12:$L$59,MAX($B$6,MIN($A15,$B$7))) -> 0.9227351 | N15: =C15/M15 -> 281.77101 | O15: =IF(AND($A15>=$B$6,$A15<=$B$7),SUMPRODUCT(Bobot_Filter!$B$20:$B$32,N9:N21),"") | P15: =IF(ISNUMBER(O15),C15/O15,"") | Q15: =IF(AND($A15+(-36)>=1,$A15+(-36)<=$B$8),INDEX($P$12:$P$59,$A15+(-36)),"") | R15: =IF(AND($A15+(-24)>=1,$A15+(-24)<=$B$8),INDEX($P$12:$P$59,$A15+(-24)),"") | S15: =IF(AND($A15+(-12)>=1,$A15+(-12)<=$B$8),INDEX($P$12:$P$59,$A15+(-12)),"") | T15: =IF(AND($A15+(0)>=1,$A15+(0)<=$B$8),INDEX($P$12:$P$59,$A15+(0)),"") | U15: =IF(AND($A15+(12)>=1,$A15+(12)<=$B$8),INDEX($P$12:$P$59,$A15+(12)),"") -> 0.89793666 | V15: =IF(AND($A15+(24)>=1,$A15+(24)<=$B$8),INDEX($P$12:$P$59,$A15+(24)),"") -> 0.97994515 | W15: =IF(AND($A15+(36)>=1,$A15+(36)<=$B$8),INDEX($P$12:$P$59,$A15+(36)),"") -> 0.95878253 | X15: =IF(SUMPRODUCT(Bobot_Filter!$B$43:$H$43,ISNUMBER(Q15:W15)*1)>0,SUMPRODUCT(Bobot_Filter!$B$43:$H$43,Q15:W15)/SUMPRODUCT(Bobot_Filter!$B$43:$H$43,ISNUMBER(Q15:W15)*1),"") -> 0.9354138 | Y15: =IF(AND($A15>=$B$6,$A15<=$B$7),SUMPRODUCT(Bobot_Filter!$B$4:$B$16,X9:X21),"") | Z15: =X15/INDEX($Y$12:$Y$59,MAX($B$6,MIN($A15,$B$7))) -> 0.93597891 | AA15: =C15/Z15 -> 277.78404 | AB15: =IF(AND($A15>=$B$6,$A15<=$B$7),SUMPRODUCT(Bobot_Filter!$B$20:$B$32,AA9:AA21),"") | AC15: =IF(ISNUMBER(AB15),AA15/AB15,"") | AD15: =$B$4+$B$3*A15 -> 260.64844 | AE15: =AD15*Z15 -> 243.96145
A16: 5 | B16: =Data!B9 -> 44470 | C16: =Data!D9 -> 252 | D16: =IF(AND($A16>=$B$6,$A16<=$B$7),SUMPRODUCT(Bobot_Filter!$B$4:$B$16,C10:C22),"") | E16: =IF(ISNUMBER(D16),C16/D16,"") | F16: =IF(AND($A16+(-24)>=1,$A16+(-24)<=$B$8),INDEX($E$12:$E$59,$A16+(-24)),"") | G16: =IF(AND($A16+(-12)>=1,$A16+(-12)<=$B$8),INDEX($E$12:$E$59,$A16+(-12)),"") | H16: =IF(AND($A16+(0)>=1,$A16+(0)<=$B$8),INDEX($E$12:$E$59,$A16+(0)),"") | I16: =IF(AND($A16+(12)>=1,$A16+(12)<=$B$8),INDEX($E$12:$E$59,$A16+(12)),"") -> 0.90036014 | J16: =IF(AND($A16+(24)>=1,$A16+(24)<=$B$8),INDEX($E$12:$E$59,$A16+(24)),"") -> 0.85171103 | K16: =IF(SUMPRODUCT(Bobot_Filter!$B$38:$F$38,ISNUMBER(F16:J16)*1)>0,SUMPRODUCT(Bobot_Filter!$B$38:$F$38,F16:J16)/SUMPRODUCT(Bobot_Filter!$B$38:$F$38,ISNUMBER(F16:J16)*1),"") -> 0.88414377 | L16: =IF(AND($A16>=$B$6,$A16<=$B$7),SUMPRODUCT(Bobot_Filter!$B$4:$B$16,K10:K22),"") | M16: =K16/INDEX($L$12:$L$59,MAX($B$6,MIN($A16,$B$7))) -> 0.88510919 | N16: =C16/M16 -> 284.71064 | O16: =IF(AND($A16>=$B$6,$A16<=$B$7),SUMPRODUCT(Bobot_Filter!$B$20:$B$32,N10:N22),"") | P16: =IF(ISNUMBER(O16),C16/O16,"") | Q16: =IF(AND($A16+(-36)>=1,$A16+(-36)<=$B$8),INDEX($P$12:$P$59,$A16+(-36)),"") | R16: =IF(AND($A16+(-24)>=1,$A16+(-24)<=$B$8),INDEX($P$12:$P$59,$A16+(-24)),"") | S16: =IF(AND($A16+(-12)>=1,$A16+(-12)<=$B$8),INDEX($P$12:$P$59,$A16+(-12)),"") | T16: =IF(AND($A16+(0)>=1,$A16+(0)<=$B$8),INDEX($P$12:$P$59,$A16+(0)),"") | U16: =IF(AND($A16+(12)>=1,$A16+(12)<=$B$8),INDEX($P$12:$P$59,$A16+(12)),"") -> 0.90726352 | V16: =IF(AND($A16+(24)>=1,$A16+(24)<=$B$8),INDEX($P$12:$P$59,$A16+(24)),"") -> 0.86013074 | W16: =IF(AND($A16+(36)>=1,$A16+(36)<=$B$8),INDEX($P$12:$P$59,$A16+(36)),"") -> 0.91930951 | X16: =IF(SUMPRODUCT(Bobot_Filter!$B$43:$H$43,ISNUMBER(Q16:W16)*1)>0,SUMPRODUCT(Bobot_Filter!$B$43:$H$43,Q16:W16)/SUMPRODUCT(Bobot_Filter!$B$43:$H$43,ISNUMBER(Q16:W16)*1),"") -> 0.89356026 | Y16: =IF(AND($A16>=$B$6,$A16<=$B$7),SUMPRODUCT(Bobot_Filter!$B$4:$B$16,X10:X22),"") | Z16: =X16/INDEX($Y$12:$Y$59,MAX($B$6,MIN($A16,$B$7))) -> 0.89410008 | AA16: =C16/Z16 -> 281.84764 | AB16: =IF(AND($A16>=$B$6,$A16<=$B$7),SUMPRODUCT(Bobot_Filter!$B$20:$B$32,AA10:AA22),"") | AC16: =IF(ISNUMBER(AB16),AA16/AB16,"") | AD16: =$B$4+$B$3*A16 -> 261.88949 | AE16: =AD16*Z16 -> 234.15541
A17: 6 | B17: =Data!B10 -> 44501 | C17: =Data!D10 -> 241 | D17: =IF(AND($A17>=$B$6,$A17<=$B$7),SUMPRODUCT(Bobot_Filter!$B$4:$B$16,C11:C23),"") | E17: =IF(ISNUMBER(D17),C17/D17,"") | F17: =IF(AND($A17+(-24)>=1,$A17+(-24)<=$B$8),INDEX($E$12:$E$59,$A17+(-24)),"") | G17: =IF(AND($A17+(-12)>=1,$A17+(-12)<=$B$8),INDEX($E$12:$E$59,$A17+(-12)),"") | H17: =IF(AND($A17+(0)>=1,$A17+(0)<=$B$8),INDEX($E$12:$E$59,$A17+(0)),"") | I17: =IF(AND($A17+(12)>=1,$A17+(12)<=$B$8),INDEX($E$12:$E$59,$A17+(12)),"") -> 0.95392954 | J17: =IF(AND($A17+(24)>=1,$A17+(24)<=$B$8),INDEX($E$12:$E$59,$A17+(24)),"") -> 0.92021427 | K17: =IF(SUMPRODUCT(Bobot_Filter!$B$38:$F$38,ISNUMBER(F17:J17)*1)>0,SUMPRODUCT(Bobot_Filter!$B$38:$F$38,F17:J17)/SUMPRODUCT(Bobot_Filter!$B$38:$F$38,ISNUMBER(F17:J17)*1),"") -> 0.94269111 | L17: =IF(AND($A17>=$B$6,$A17<=$B$7),SUMPRODUCT(Bobot_Filter!$B$4:$B$16,K11:K23),"") | M17: =K17/INDEX($L$12:$L$59,MAX($B$6,MIN($A17,$B$7))) -> 0.94372046 | N17: =C17/M17 -> 255.37223 | O17: =IF(AND($A17>=$B$6,$A17<=$B$7),SUMPRODUCT(Bobot_Filter!$B$20:$B$32,N11:N23),"") | P17: =IF(ISNUMBER(O17),C17/O17,"") | Q17: =IF(AND($A17+(-36)>=1,$A17+(-36)<=$B$8),INDEX($P$12:$P$59,$A17+(-36)),"") | R17: =IF(AND($A17+(-24)>=1,$A17+(-24)<=$B$8),INDEX($P$12:$P$59,$A17+(-24)),"") | S17: =IF(AND($A17+(-12)>=1,$A17+(-12)<=$B$8),INDEX($P$12:$P$59,$A17+(-12)),"") | T17: =IF(AND($A17+(0)>=1,$A17+(0)<=$B$8),INDEX($P$12:$P$59,$A17+(0)),"") | U17: =IF(AND($A17+(12)>=1,$A17+(12)<=$B$8),INDEX($P$12:$P$59,$A17+(12)),"") -> 0.95402571 | V17: =IF(AND($A17+(24)>=1,$A17+(24)<=$B$8),INDEX($P$12:$P$59,$A17+(24)),"") -> 0.9212082 | W17: =IF(AND($A17+(36)>=1,$A17+(36)<=$B$8),INDEX($P$12:$P$59,$A17+(36)),"") -> 0.87769545 | X17: =IF(SUMPRODUCT(Bobot_Filter!$B$43:$H$43,ISNUMBER(Q17:W17)*1)>0,SUMPRODUCT(Bobot_Filter!$B$43:$H$43,Q17:W17)/SUMPRODUCT(Bobot_Filter!$B$43:$H$43,ISNUMBER(Q17:W17)*1),"") -> 0.93036483 | Y17: =IF(AND($A17>=$B$6,$A17<=$B$7),SUMPRODUCT(Bobot_Filter!$B$4:$B$16,X11:X23),"") | Z17: =X17/INDEX($Y$12:$Y$59,MAX($B$6,MIN($A17,$B$7))) -> 0.93092689 | AA17: =C17/Z17 -> 258.88177 | AB17: =IF(AND($A17>=$B$6,$A17<=$B$7),SUMPRODUCT(Bobot_Filter!$B$20:$B$32,AA11:AA23),"") | AC17: =IF(ISNUMBER(AB17),AA17/AB17,"") | AD17: =$B$4+$B$3*A17 -> 263.13054 | AE17: =AD17*Z17 -> 244.95529
A18: 7 | B18: =Data!B11 -> 44531 | C18: =Data!D11 -> 302 | D18: =IF(AND($A18>=$B$6,$A18<=$B$7),SUMPRODUCT(Bobot_Filter!$B$4:$B$16,C12:C24),"") -> 266.375 | E18: =IF(ISNUMBER(D18),C18/D18,"") -> 1.13374 | F18: =IF(AND($A18+(-24)>=1,$A18+(-24)<=$B$8),INDEX($E$12:$E$59,$A18+(-24)),"") | G18: =IF(AND($A18+(-12)>=1,$A18+(-12)<=$B$8),INDEX($E$12:$E$59,$A18+(-12)),"") | H18: =IF(AND($A18+(0)>=1,$A18+(0)<=$B$8),INDEX($E$12:$E$59,$A18+(0)),"") -> 1.13374 | I18: =IF(AND($A18+(12)>=1,$A18+(12)<=$B$8),INDEX($E$12:$E$59,$A18+(12)),"") -> 1.1574981 | J18: =IF(AND($A18+(24)>=1,$A18+(24)<=$B$8),INDEX($E$12:$E$59,$A18+(24)),"") -> 1.0758853 | K18: =IF(SUMPRODUCT(Bobot_Filter!$B$38:$F$38,ISNUMBER(F18:J18)*1)>0,SUMPRODUCT(Bobot_Filter!$B$38:$F$38,F18:J18)/SUMPRODUCT(Bobot_Filter!$B$38:$F$38,ISNUMBER(F18:J18)*1),"") -> 1.1320169 | L18: =IF(AND($A18>=$B$6,$A18<=$B$7),SUMPRODUCT(Bobot_Filter!$B$4:$B$16,K12:K24),"") -> 0.99890927 | M18: =K18/INDEX($L$12:$L$59,MAX($B$6,MIN($A18,$B$7))) -> 1.133253 | N18: =C18/M18 -> 266.48947 | O18: =IF(AND($A18>=$B$6,$A18<=$B$7),SUMPRODUCT(Bobot_Filter!$B$20:$B$32,N12:N24),"") -> 267.44186 | P18: =IF(ISNUMBER(O18),C18/O18,"") -> 1.1292174 | Q18: =IF(AND($A18+(-36)>=1,$A18+(-36)<=$B$8),INDEX($P$12:$P$59,$A18+(-36)),"") | R18: =IF(AND($A18+(-24)>=1,$A18+(-24)<=$B$8),INDEX($P$12:$P$59,$A18+(-24)),"") | S18: =IF(AND($A18+(-12)>=1,$A18+(-12)<=$B$8),INDEX($P$12:$P$59,$A18+(-12)),"") | T18: =IF(AND($A18+(0)>=1,$A18+(0)<=$B$8),INDEX($P$12:$P$59,$A18+(0)),"") -> 1.1292174 | U18: =IF(AND($A18+(12)>=1,$A18+(12)<=$B$8),INDEX($P$12:$P$59,$A18+(12)),"") -> 1.1545677 | V18: =IF(AND($A18+(24)>=1,$A18+(24)<=$B$8),INDEX($P$12:$P$59,$A18+(24)),"") -> 1.0695491 | W18: =IF(AND($A18+(36)>=1,$A18+(36)<=$B$8),INDEX($P$12:$P$59,$A18+(36)),"") | X18: =IF(SUMPRODUCT(Bobot_Filter!$B$43:$H$43,ISNUMBER(Q18:W18)*1)>0,SUMPRODUCT(Bobot_Filter!$B$43:$H$43,Q18:W18)/SUMPRODUCT(Bobot_Filter!$B$43:$H$43,ISNUMBER(Q18:W18)*1),"") -> 1.1238067 | Y18: =IF(AND($A18>=$B$6,$A18<=$B$7),SUMPRODUCT(Bobot_Filter!$B$4:$B$16,X12:X24),"") -> 0.99939624 | Z18: =X18/INDEX($Y$12:$Y$59,MAX($B$6,MIN($A18,$B$7))) -> 1.1244856 | AA18: =C18/Z18 -> 268.56724 | AB18: =IF(AND($A18>=$B$6,$A18<=$B$7),SUMPRODUCT(Bobot_Filter!$B$20:$B$32,AA12:AA24),"") -> 266.84012 | AC18: =IF(ISNUMBER(AB18),AA18/AB18,"") -> 1.0064725 | AD18: =$B$4+$B$3*A18 -> 264.37159 | AE18: =AD18*Z18 -> 297.28204
A19: 8 | B19: =Data!B12 -> 44562 | C19: =Data!D12 -> 288 | D19: =IF(AND($A19>=$B$6,$A19<=$B$7),SUMPRODUCT(Bobot_Filter!$B$4:$B$16,C13:C25),"") -> 267.625 | E19: =IF(ISNUMBER(D19),C19/D19,"") -> 1.0761326 | F19: =IF(AND($A19+(-24)>=1,$A19+(-24)<=$B$8),INDEX($E$12:$E$59,$A19+(-24)),"") | G19: =IF(AND($A19+(-12)>=1,$A19+(-12)<=$B$8),INDEX($E$12:$E$59,$A19+(-12)),"") | H19: =IF(AND($A19+(0)>=1,$A19+(0)<=$B$8),INDEX($E$12:$E$59,$A19+(0)),"") -> 1.0761326 | I19: =IF(AND($A19+(12)>=1,$A19+(12)<=$B$8),INDEX($E$12:$E$59,$A19+(12)),"") -> 0.99611824 | J19: =IF(AND($A19+(24)>=1,$A19+(24)<=$B$8),INDEX($E$12:$E$59,$A19+(24)),"") -> 1.129969 | K19: =IF(SUMPRODUCT(Bobot_Filter!$B$38:$F$38,ISNUMBER(F19:J19)*1)>0,SUMPRODUCT(Bobot_Filter!$B$38:$F$38,F19:J19)/SUMPRODUCT(Bobot_Filter!$B$38:$F$38,ISNUMBER(F19:J19)*1),"") -> 1.0584339 | L19: =IF(AND($A19>=$B$6,$A19<=$B$7),SUMPRODUCT(Bobot_Filter!$B$4:$B$16,K13:K25),"") -> 0.99852878 | M19: =K19/INDEX($L$12:$L$59,MAX($B$6,MIN($A19,$B$7))) -> 1.0599934 | N19: =C19/M19 -> 271.69981 | O19: =IF(AND($A19>=$B$6,$A19<=$B$7),SUMPRODUCT(Bobot_Filter!$B$20:$B$32,N13:N25),"") -> 265.85045 | P19: =IF(ISNUMBER(O19),C19/O19,"") -> 1.0833158 | Q19: =IF(AND($A19+(-36)>=1,$A19+(-36)<=$B$8),INDEX($P$12:$P$59,$A19+(-36)),"") | R19: =IF(AND($A19+(-24)>=1,$A19+(-24)<=$B$8),INDEX($P$12:$P$59,$A19+(-24)),"") | S19: =IF(AND($A19+(-12)>=1,$A19+(-12)<=$B$8),INDEX($P$12:$P$59,$A19+(-12)),"") | T19: =IF(AND($A19+(0)>=1,$A19+(0)<=$B$8),INDEX($P$12:$P$59,$A19+(0)),"") -> 1.0833158 | U19: =IF(AND($A19+(12)>=1,$A19+(12)<=$B$8),INDEX($P$12:$P$59,$A19+(12)),"") -> 1.0049103 | V19: =IF(AND($A19+(24)>=1,$A19+(24)<=$B$8),INDEX($P$12:$P$59,$A19+(24)),"") -> 1.1083771 | W19: =IF(AND($A19+(36)>=1,$A19+(36)<=$B$8),INDEX($P$12:$P$59,$A19+(36)),"") | X19: =IF(SUMPRODUCT(Bobot_Filter!$B$43:$H$43,ISNUMBER(Q19:W19)*1)>0,SUMPRODUCT(Bobot_Filter!$B$43:$H$43,Q19:W19)/SUMPRODUCT(Bobot_Filter!$B$43:$H$43,ISNUMBER(Q19:W19)*1),"") -> 1.0601791 | Y19: =IF(AND($A19>=$B$6,$A19<=$B$7),SUMPRODUCT(Bobot_Filter!$B$4:$B$16,X13:X25),"") -> 0.99955524 | Z19: =X19/INDEX($Y$12:$Y$59,MAX($B$6,MIN($A19,$B$7))) -> 1.0606508 | AA19: =C19/Z19 -> 271.5314 | AB19: =IF(AND($A19>=$B$6,$A19<=$B$7),SUMPRODUCT(Bobot_Filter!$B$20:$B$32,AA13:AA25),"") -> 264.99932 | AC19: =IF(ISNUMBER(AB19),AA19/AB19,"") -> 1.0246494 | AD19: =$B$4+$B$3*A19 -> 265.61263 | AE19: =AD19*Z19 -> 281.72226
A20: 9 | B20: =Data!B13 -> 44593 | C20: =Data!D13 -> 244 | D20: =IF(AND($A20>=$B$6,$A20<=$B$7),SUMPRODUCT(Bobot_Filter!$B$4:$B$16,C14:C26),"") -> 269.5 | E20: =IF(ISNUMBER(D20),C20/D20,"") -> 0.90538033 | F20: =IF(AND($A20+(-24)>=1,$A20+(-24)<=$B$8),INDEX($E$12:$E$59,$A20+(-24)),"") | G20: =IF(AND($A20+(-12)>=1,$A20+(-12)<=$B$8),INDEX($E$12:$E$59,$A20+(-12)),"") | H20: =IF(AND($A20+(0)>=1,$A20+(0)<=$B$8),INDEX($E$12:$E$59,$A20+(0)),"") -> 0.90538033 | I20: =IF(AND($A20+(12)>=1,$A20+(12)<=$B$8),INDEX($E$12:$E$59,$A20+(12)),"") -> 0.90431687 | J20: =IF(AND($A20+(24)>=1,$A20+(24)<=$B$8),INDEX($E$12:$E$59,$A20+(24)),"") -> 0.95959454 | K20: =IF(SUMPRODUCT(Bobot_Filter!$B$38:$F$38,ISNUMBER(F20:J20)*1)>0,SUMPRODUCT(Bobot_Filter!$B$38:$F$38,F20:J20)/SUMPRODUCT(Bobot_Filter!$B$38:$F$38,ISNUMBER(F20:J20)*1),"") -> 0.91406155 | L20: =IF(AND($A20>=$B$6,$A20<=$B$7),SUMPRODUCT(Bobot_Filter!$B$4:$B$16,K14:K26),"") -> 0.99833692 | M20: =K20/INDEX($L$12:$L$59,MAX($B$6,MIN($A20,$B$7))) -> 0.91558423 | N20: =C20/M20 -> 266.49651 | O20: =IF(AND($A20>=$B$6,$A20<=$B$7),SUMPRODUCT(Bobot_Filter!$B$20:$B$32,N14:N26),"") -> 265.61167 | P20: =IF(ISNUMBER(O20),C20/O20,"") -> 0.91863435 | Q20: =IF(AND($A20+(-36)>=1,$A20+(-36)<=$B$8),INDEX($P$12:$P$59,$A20+(-36)),"") | R20: =IF(AND($A20+(-24)>=1,$A20+(-24)<=$B$8),INDEX($P$12:$P$59,$A20+(-24)),"") | S20: =IF(AND($A20+(-12)>=1,$A20+(-12)<=$B$8),INDEX($P$12:$P$59,$A20+(-12)),"") | T20: =IF(AND($A20+(0)>=1,$A20+(0)<=$B$8),INDEX($P$12:$P$59,$A20+(0)),"") -> 0.91863435 | U20: =IF(AND($A20+(12)>=1,$A20+(12)<=$B$8),INDEX($P$12:$P$59,$A20+(12)),"") -> 0.91723556 | V20: =IF(AND($A20+(24)>=1,$A20+(24)<=$B$8),INDEX($P$12:$P$59,$A20+(24)),"") -> 0.93943921 | W20: =IF(AND($A20+(36)>=1,$A20+(36)<=$B$8),INDEX($P$12:$P$59,$A20+(36)),"") | X20: =IF(SUMPRODUCT(Bobot_Filter!$B$43:$H$43,ISNUMBER(Q20:W20)*1)>0,SUMPRODUCT(Bobot_Filter!$B$43:$H$43,Q20:W20)/SUMPRODUCT(Bobot_Filter!$B$43:$H$43,ISNUMBER(Q20:W20)*1),"") -> 0.92331102 | Y20: =IF(AND($A20>=$B$6,$A20<=$B$7),SUMPRODUCT(Bobot_Filter!$B$4:$B$16,X14:X26),"") -> 0.99965244 | Z20: =X20/INDEX($Y$12:$Y$59,MAX($B$6,MIN($A20,$B$7))) -> 0.92363204 | AA20: =C20/Z20 -> 264.17447 | AB20: =IF(AND($A20>=$B$6,$A20<=$B$7),SUMPRODUCT(Bobot_Filter!$B$20:$B$32,AA14:AA26),"") -> 264.66357 | AC20: =IF(ISNUMBER(AB20),AA20/AB20,"") -> 0.99815197 | AD20: =$B$4+$B$3*A20 -> 266.85368 | AE20: =AD20*Z20 -> 246.47461
